{
 "cells": [
  {
   "cell_type": "code",
   "execution_count": null,
   "metadata": {},
   "outputs": [
    {
     "name": "stderr",
     "output_type": "stream",
     "text": [
      "Error while getting Updates: Conflict: terminated by other getUpdates request; make sure that only one bot instance is running\n",
      "No error handlers are registered, logging exception.\n",
      "Traceback (most recent call last):\n",
      "  File \"C:\\Users\\JABIR\\AppData\\Roaming\\Python\\Python38\\site-packages\\telegram\\ext\\updater.py\", line 646, in _network_loop_retry\n",
      "    if not action_cb():\n",
      "  File \"C:\\Users\\JABIR\\AppData\\Roaming\\Python\\Python38\\site-packages\\telegram\\ext\\updater.py\", line 597, in polling_action_cb\n",
      "    updates = self.bot.get_updates(\n",
      "  File \"C:\\Users\\JABIR\\AppData\\Roaming\\Python\\Python38\\site-packages\\telegram\\ext\\extbot.py\", line 222, in get_updates\n",
      "    updates = super().get_updates(\n",
      "  File \"C:\\Users\\JABIR\\AppData\\Roaming\\Python\\Python38\\site-packages\\telegram\\bot.py\", line 130, in decorator\n",
      "    result = func(*args, **kwargs)\n",
      "  File \"C:\\Users\\JABIR\\AppData\\Roaming\\Python\\Python38\\site-packages\\telegram\\bot.py\", line 2861, in get_updates\n",
      "    self._post(\n",
      "  File \"C:\\Users\\JABIR\\AppData\\Roaming\\Python\\Python38\\site-packages\\telegram\\bot.py\", line 295, in _post\n",
      "    return self.request.post(\n",
      "  File \"C:\\Users\\JABIR\\AppData\\Roaming\\Python\\Python38\\site-packages\\telegram\\utils\\request.py\", line 356, in post\n",
      "    result = self._request_wrapper(\n",
      "  File \"C:\\Users\\JABIR\\AppData\\Roaming\\Python\\Python38\\site-packages\\telegram\\utils\\request.py\", line 283, in _request_wrapper\n",
      "    raise Conflict(message)\n",
      "telegram.error.Conflict: Conflict: terminated by other getUpdates request; make sure that only one bot instance is running\n",
      "Error while getting Updates: Conflict: terminated by other getUpdates request; make sure that only one bot instance is running\n",
      "No error handlers are registered, logging exception.\n",
      "Traceback (most recent call last):\n",
      "  File \"C:\\Users\\JABIR\\AppData\\Roaming\\Python\\Python38\\site-packages\\telegram\\ext\\updater.py\", line 646, in _network_loop_retry\n",
      "    if not action_cb():\n",
      "  File \"C:\\Users\\JABIR\\AppData\\Roaming\\Python\\Python38\\site-packages\\telegram\\ext\\updater.py\", line 597, in polling_action_cb\n",
      "    updates = self.bot.get_updates(\n",
      "  File \"C:\\Users\\JABIR\\AppData\\Roaming\\Python\\Python38\\site-packages\\telegram\\ext\\extbot.py\", line 222, in get_updates\n",
      "    updates = super().get_updates(\n",
      "  File \"C:\\Users\\JABIR\\AppData\\Roaming\\Python\\Python38\\site-packages\\telegram\\bot.py\", line 130, in decorator\n",
      "    result = func(*args, **kwargs)\n",
      "  File \"C:\\Users\\JABIR\\AppData\\Roaming\\Python\\Python38\\site-packages\\telegram\\bot.py\", line 2861, in get_updates\n",
      "    self._post(\n",
      "  File \"C:\\Users\\JABIR\\AppData\\Roaming\\Python\\Python38\\site-packages\\telegram\\bot.py\", line 295, in _post\n",
      "    return self.request.post(\n",
      "  File \"C:\\Users\\JABIR\\AppData\\Roaming\\Python\\Python38\\site-packages\\telegram\\utils\\request.py\", line 356, in post\n",
      "    result = self._request_wrapper(\n",
      "  File \"C:\\Users\\JABIR\\AppData\\Roaming\\Python\\Python38\\site-packages\\telegram\\utils\\request.py\", line 283, in _request_wrapper\n",
      "    raise Conflict(message)\n",
      "telegram.error.Conflict: Conflict: terminated by other getUpdates request; make sure that only one bot instance is running\n",
      "Error while getting Updates: Conflict: terminated by other getUpdates request; make sure that only one bot instance is running\n",
      "No error handlers are registered, logging exception.\n",
      "Traceback (most recent call last):\n",
      "  File \"C:\\Users\\JABIR\\AppData\\Roaming\\Python\\Python38\\site-packages\\telegram\\ext\\updater.py\", line 646, in _network_loop_retry\n",
      "    if not action_cb():\n",
      "  File \"C:\\Users\\JABIR\\AppData\\Roaming\\Python\\Python38\\site-packages\\telegram\\ext\\updater.py\", line 597, in polling_action_cb\n",
      "    updates = self.bot.get_updates(\n",
      "  File \"C:\\Users\\JABIR\\AppData\\Roaming\\Python\\Python38\\site-packages\\telegram\\ext\\extbot.py\", line 222, in get_updates\n",
      "    updates = super().get_updates(\n",
      "  File \"C:\\Users\\JABIR\\AppData\\Roaming\\Python\\Python38\\site-packages\\telegram\\bot.py\", line 130, in decorator\n",
      "    result = func(*args, **kwargs)\n",
      "  File \"C:\\Users\\JABIR\\AppData\\Roaming\\Python\\Python38\\site-packages\\telegram\\bot.py\", line 2861, in get_updates\n",
      "    self._post(\n",
      "  File \"C:\\Users\\JABIR\\AppData\\Roaming\\Python\\Python38\\site-packages\\telegram\\bot.py\", line 295, in _post\n",
      "    return self.request.post(\n",
      "  File \"C:\\Users\\JABIR\\AppData\\Roaming\\Python\\Python38\\site-packages\\telegram\\utils\\request.py\", line 356, in post\n",
      "    result = self._request_wrapper(\n",
      "  File \"C:\\Users\\JABIR\\AppData\\Roaming\\Python\\Python38\\site-packages\\telegram\\utils\\request.py\", line 283, in _request_wrapper\n",
      "    raise Conflict(message)\n",
      "telegram.error.Conflict: Conflict: terminated by other getUpdates request; make sure that only one bot instance is running\n",
      "Error while getting Updates: Conflict: terminated by other getUpdates request; make sure that only one bot instance is running\n",
      "No error handlers are registered, logging exception.\n",
      "Traceback (most recent call last):\n",
      "  File \"C:\\Users\\JABIR\\AppData\\Roaming\\Python\\Python38\\site-packages\\telegram\\ext\\updater.py\", line 646, in _network_loop_retry\n",
      "    if not action_cb():\n",
      "  File \"C:\\Users\\JABIR\\AppData\\Roaming\\Python\\Python38\\site-packages\\telegram\\ext\\updater.py\", line 597, in polling_action_cb\n",
      "    updates = self.bot.get_updates(\n",
      "  File \"C:\\Users\\JABIR\\AppData\\Roaming\\Python\\Python38\\site-packages\\telegram\\ext\\extbot.py\", line 222, in get_updates\n",
      "    updates = super().get_updates(\n",
      "  File \"C:\\Users\\JABIR\\AppData\\Roaming\\Python\\Python38\\site-packages\\telegram\\bot.py\", line 130, in decorator\n",
      "    result = func(*args, **kwargs)\n",
      "  File \"C:\\Users\\JABIR\\AppData\\Roaming\\Python\\Python38\\site-packages\\telegram\\bot.py\", line 2861, in get_updates\n",
      "    self._post(\n",
      "  File \"C:\\Users\\JABIR\\AppData\\Roaming\\Python\\Python38\\site-packages\\telegram\\bot.py\", line 295, in _post\n",
      "    return self.request.post(\n",
      "  File \"C:\\Users\\JABIR\\AppData\\Roaming\\Python\\Python38\\site-packages\\telegram\\utils\\request.py\", line 356, in post\n",
      "    result = self._request_wrapper(\n",
      "  File \"C:\\Users\\JABIR\\AppData\\Roaming\\Python\\Python38\\site-packages\\telegram\\utils\\request.py\", line 283, in _request_wrapper\n",
      "    raise Conflict(message)\n",
      "telegram.error.Conflict: Conflict: terminated by other getUpdates request; make sure that only one bot instance is running\n",
      "Error while getting Updates: Conflict: terminated by other getUpdates request; make sure that only one bot instance is running\n",
      "No error handlers are registered, logging exception.\n",
      "Traceback (most recent call last):\n",
      "  File \"C:\\Users\\JABIR\\AppData\\Roaming\\Python\\Python38\\site-packages\\telegram\\ext\\updater.py\", line 646, in _network_loop_retry\n",
      "    if not action_cb():\n",
      "  File \"C:\\Users\\JABIR\\AppData\\Roaming\\Python\\Python38\\site-packages\\telegram\\ext\\updater.py\", line 597, in polling_action_cb\n",
      "    updates = self.bot.get_updates(\n",
      "  File \"C:\\Users\\JABIR\\AppData\\Roaming\\Python\\Python38\\site-packages\\telegram\\ext\\extbot.py\", line 222, in get_updates\n",
      "    updates = super().get_updates(\n",
      "  File \"C:\\Users\\JABIR\\AppData\\Roaming\\Python\\Python38\\site-packages\\telegram\\bot.py\", line 130, in decorator\n",
      "    result = func(*args, **kwargs)\n",
      "  File \"C:\\Users\\JABIR\\AppData\\Roaming\\Python\\Python38\\site-packages\\telegram\\bot.py\", line 2861, in get_updates\n",
      "    self._post(\n",
      "  File \"C:\\Users\\JABIR\\AppData\\Roaming\\Python\\Python38\\site-packages\\telegram\\bot.py\", line 295, in _post\n",
      "    return self.request.post(\n",
      "  File \"C:\\Users\\JABIR\\AppData\\Roaming\\Python\\Python38\\site-packages\\telegram\\utils\\request.py\", line 356, in post\n",
      "    result = self._request_wrapper(\n",
      "  File \"C:\\Users\\JABIR\\AppData\\Roaming\\Python\\Python38\\site-packages\\telegram\\utils\\request.py\", line 283, in _request_wrapper\n",
      "    raise Conflict(message)\n",
      "telegram.error.Conflict: Conflict: terminated by other getUpdates request; make sure that only one bot instance is running\n",
      "Error while getting Updates: Conflict: terminated by other getUpdates request; make sure that only one bot instance is running\n",
      "No error handlers are registered, logging exception.\n",
      "Traceback (most recent call last):\n",
      "  File \"C:\\Users\\JABIR\\AppData\\Roaming\\Python\\Python38\\site-packages\\telegram\\ext\\updater.py\", line 646, in _network_loop_retry\n",
      "    if not action_cb():\n",
      "  File \"C:\\Users\\JABIR\\AppData\\Roaming\\Python\\Python38\\site-packages\\telegram\\ext\\updater.py\", line 597, in polling_action_cb\n",
      "    updates = self.bot.get_updates(\n",
      "  File \"C:\\Users\\JABIR\\AppData\\Roaming\\Python\\Python38\\site-packages\\telegram\\ext\\extbot.py\", line 222, in get_updates\n",
      "    updates = super().get_updates(\n",
      "  File \"C:\\Users\\JABIR\\AppData\\Roaming\\Python\\Python38\\site-packages\\telegram\\bot.py\", line 130, in decorator\n",
      "    result = func(*args, **kwargs)\n",
      "  File \"C:\\Users\\JABIR\\AppData\\Roaming\\Python\\Python38\\site-packages\\telegram\\bot.py\", line 2861, in get_updates\n",
      "    self._post(\n",
      "  File \"C:\\Users\\JABIR\\AppData\\Roaming\\Python\\Python38\\site-packages\\telegram\\bot.py\", line 295, in _post\n",
      "    return self.request.post(\n",
      "  File \"C:\\Users\\JABIR\\AppData\\Roaming\\Python\\Python38\\site-packages\\telegram\\utils\\request.py\", line 356, in post\n",
      "    result = self._request_wrapper(\n",
      "  File \"C:\\Users\\JABIR\\AppData\\Roaming\\Python\\Python38\\site-packages\\telegram\\utils\\request.py\", line 283, in _request_wrapper\n",
      "    raise Conflict(message)\n",
      "telegram.error.Conflict: Conflict: terminated by other getUpdates request; make sure that only one bot instance is running\n"
     ]
    },
    {
     "name": "stderr",
     "output_type": "stream",
     "text": [
      "Error while getting Updates: Conflict: terminated by other getUpdates request; make sure that only one bot instance is running\n",
      "No error handlers are registered, logging exception.\n",
      "Traceback (most recent call last):\n",
      "  File \"C:\\Users\\JABIR\\AppData\\Roaming\\Python\\Python38\\site-packages\\telegram\\ext\\updater.py\", line 646, in _network_loop_retry\n",
      "    if not action_cb():\n",
      "  File \"C:\\Users\\JABIR\\AppData\\Roaming\\Python\\Python38\\site-packages\\telegram\\ext\\updater.py\", line 597, in polling_action_cb\n",
      "    updates = self.bot.get_updates(\n",
      "  File \"C:\\Users\\JABIR\\AppData\\Roaming\\Python\\Python38\\site-packages\\telegram\\ext\\extbot.py\", line 222, in get_updates\n",
      "    updates = super().get_updates(\n",
      "  File \"C:\\Users\\JABIR\\AppData\\Roaming\\Python\\Python38\\site-packages\\telegram\\bot.py\", line 130, in decorator\n",
      "    result = func(*args, **kwargs)\n",
      "  File \"C:\\Users\\JABIR\\AppData\\Roaming\\Python\\Python38\\site-packages\\telegram\\bot.py\", line 2861, in get_updates\n",
      "    self._post(\n",
      "  File \"C:\\Users\\JABIR\\AppData\\Roaming\\Python\\Python38\\site-packages\\telegram\\bot.py\", line 295, in _post\n",
      "    return self.request.post(\n",
      "  File \"C:\\Users\\JABIR\\AppData\\Roaming\\Python\\Python38\\site-packages\\telegram\\utils\\request.py\", line 356, in post\n",
      "    result = self._request_wrapper(\n",
      "  File \"C:\\Users\\JABIR\\AppData\\Roaming\\Python\\Python38\\site-packages\\telegram\\utils\\request.py\", line 283, in _request_wrapper\n",
      "    raise Conflict(message)\n",
      "telegram.error.Conflict: Conflict: terminated by other getUpdates request; make sure that only one bot instance is running\n",
      "Error while getting Updates: Conflict: terminated by other getUpdates request; make sure that only one bot instance is running\n",
      "No error handlers are registered, logging exception.\n",
      "Traceback (most recent call last):\n",
      "  File \"C:\\Users\\JABIR\\AppData\\Roaming\\Python\\Python38\\site-packages\\telegram\\ext\\updater.py\", line 646, in _network_loop_retry\n",
      "    if not action_cb():\n",
      "  File \"C:\\Users\\JABIR\\AppData\\Roaming\\Python\\Python38\\site-packages\\telegram\\ext\\updater.py\", line 597, in polling_action_cb\n",
      "    updates = self.bot.get_updates(\n",
      "  File \"C:\\Users\\JABIR\\AppData\\Roaming\\Python\\Python38\\site-packages\\telegram\\ext\\extbot.py\", line 222, in get_updates\n",
      "    updates = super().get_updates(\n",
      "  File \"C:\\Users\\JABIR\\AppData\\Roaming\\Python\\Python38\\site-packages\\telegram\\bot.py\", line 130, in decorator\n",
      "    result = func(*args, **kwargs)\n",
      "  File \"C:\\Users\\JABIR\\AppData\\Roaming\\Python\\Python38\\site-packages\\telegram\\bot.py\", line 2861, in get_updates\n",
      "    self._post(\n",
      "  File \"C:\\Users\\JABIR\\AppData\\Roaming\\Python\\Python38\\site-packages\\telegram\\bot.py\", line 295, in _post\n",
      "    return self.request.post(\n",
      "  File \"C:\\Users\\JABIR\\AppData\\Roaming\\Python\\Python38\\site-packages\\telegram\\utils\\request.py\", line 356, in post\n",
      "    result = self._request_wrapper(\n",
      "  File \"C:\\Users\\JABIR\\AppData\\Roaming\\Python\\Python38\\site-packages\\telegram\\utils\\request.py\", line 283, in _request_wrapper\n",
      "    raise Conflict(message)\n",
      "telegram.error.Conflict: Conflict: terminated by other getUpdates request; make sure that only one bot instance is running\n",
      "Error while getting Updates: Conflict: terminated by other getUpdates request; make sure that only one bot instance is running\n",
      "No error handlers are registered, logging exception.\n",
      "Traceback (most recent call last):\n",
      "  File \"C:\\Users\\JABIR\\AppData\\Roaming\\Python\\Python38\\site-packages\\telegram\\ext\\updater.py\", line 646, in _network_loop_retry\n",
      "    if not action_cb():\n",
      "  File \"C:\\Users\\JABIR\\AppData\\Roaming\\Python\\Python38\\site-packages\\telegram\\ext\\updater.py\", line 597, in polling_action_cb\n",
      "    updates = self.bot.get_updates(\n",
      "  File \"C:\\Users\\JABIR\\AppData\\Roaming\\Python\\Python38\\site-packages\\telegram\\ext\\extbot.py\", line 222, in get_updates\n",
      "    updates = super().get_updates(\n",
      "  File \"C:\\Users\\JABIR\\AppData\\Roaming\\Python\\Python38\\site-packages\\telegram\\bot.py\", line 130, in decorator\n",
      "    result = func(*args, **kwargs)\n",
      "  File \"C:\\Users\\JABIR\\AppData\\Roaming\\Python\\Python38\\site-packages\\telegram\\bot.py\", line 2861, in get_updates\n",
      "    self._post(\n",
      "  File \"C:\\Users\\JABIR\\AppData\\Roaming\\Python\\Python38\\site-packages\\telegram\\bot.py\", line 295, in _post\n",
      "    return self.request.post(\n",
      "  File \"C:\\Users\\JABIR\\AppData\\Roaming\\Python\\Python38\\site-packages\\telegram\\utils\\request.py\", line 356, in post\n",
      "    result = self._request_wrapper(\n",
      "  File \"C:\\Users\\JABIR\\AppData\\Roaming\\Python\\Python38\\site-packages\\telegram\\utils\\request.py\", line 283, in _request_wrapper\n",
      "    raise Conflict(message)\n",
      "telegram.error.Conflict: Conflict: terminated by other getUpdates request; make sure that only one bot instance is running\n",
      "Error while getting Updates: Conflict: terminated by other getUpdates request; make sure that only one bot instance is running\n",
      "No error handlers are registered, logging exception.\n",
      "Traceback (most recent call last):\n",
      "  File \"C:\\Users\\JABIR\\AppData\\Roaming\\Python\\Python38\\site-packages\\telegram\\ext\\updater.py\", line 646, in _network_loop_retry\n",
      "    if not action_cb():\n",
      "  File \"C:\\Users\\JABIR\\AppData\\Roaming\\Python\\Python38\\site-packages\\telegram\\ext\\updater.py\", line 597, in polling_action_cb\n",
      "    updates = self.bot.get_updates(\n",
      "  File \"C:\\Users\\JABIR\\AppData\\Roaming\\Python\\Python38\\site-packages\\telegram\\ext\\extbot.py\", line 222, in get_updates\n",
      "    updates = super().get_updates(\n",
      "  File \"C:\\Users\\JABIR\\AppData\\Roaming\\Python\\Python38\\site-packages\\telegram\\bot.py\", line 130, in decorator\n",
      "    result = func(*args, **kwargs)\n",
      "  File \"C:\\Users\\JABIR\\AppData\\Roaming\\Python\\Python38\\site-packages\\telegram\\bot.py\", line 2861, in get_updates\n",
      "    self._post(\n",
      "  File \"C:\\Users\\JABIR\\AppData\\Roaming\\Python\\Python38\\site-packages\\telegram\\bot.py\", line 295, in _post\n",
      "    return self.request.post(\n",
      "  File \"C:\\Users\\JABIR\\AppData\\Roaming\\Python\\Python38\\site-packages\\telegram\\utils\\request.py\", line 356, in post\n",
      "    result = self._request_wrapper(\n",
      "  File \"C:\\Users\\JABIR\\AppData\\Roaming\\Python\\Python38\\site-packages\\telegram\\utils\\request.py\", line 283, in _request_wrapper\n",
      "    raise Conflict(message)\n",
      "telegram.error.Conflict: Conflict: terminated by other getUpdates request; make sure that only one bot instance is running\n",
      "Error while getting Updates: Conflict: terminated by other getUpdates request; make sure that only one bot instance is running\n",
      "No error handlers are registered, logging exception.\n",
      "Traceback (most recent call last):\n",
      "  File \"C:\\Users\\JABIR\\AppData\\Roaming\\Python\\Python38\\site-packages\\telegram\\ext\\updater.py\", line 646, in _network_loop_retry\n",
      "    if not action_cb():\n",
      "  File \"C:\\Users\\JABIR\\AppData\\Roaming\\Python\\Python38\\site-packages\\telegram\\ext\\updater.py\", line 597, in polling_action_cb\n",
      "    updates = self.bot.get_updates(\n",
      "  File \"C:\\Users\\JABIR\\AppData\\Roaming\\Python\\Python38\\site-packages\\telegram\\ext\\extbot.py\", line 222, in get_updates\n",
      "    updates = super().get_updates(\n",
      "  File \"C:\\Users\\JABIR\\AppData\\Roaming\\Python\\Python38\\site-packages\\telegram\\bot.py\", line 130, in decorator\n",
      "    result = func(*args, **kwargs)\n",
      "  File \"C:\\Users\\JABIR\\AppData\\Roaming\\Python\\Python38\\site-packages\\telegram\\bot.py\", line 2861, in get_updates\n",
      "    self._post(\n",
      "  File \"C:\\Users\\JABIR\\AppData\\Roaming\\Python\\Python38\\site-packages\\telegram\\bot.py\", line 295, in _post\n",
      "    return self.request.post(\n",
      "  File \"C:\\Users\\JABIR\\AppData\\Roaming\\Python\\Python38\\site-packages\\telegram\\utils\\request.py\", line 356, in post\n",
      "    result = self._request_wrapper(\n",
      "  File \"C:\\Users\\JABIR\\AppData\\Roaming\\Python\\Python38\\site-packages\\telegram\\utils\\request.py\", line 283, in _request_wrapper\n",
      "    raise Conflict(message)\n",
      "telegram.error.Conflict: Conflict: terminated by other getUpdates request; make sure that only one bot instance is running\n",
      "Error while getting Updates: Conflict: terminated by other getUpdates request; make sure that only one bot instance is running\n",
      "No error handlers are registered, logging exception.\n",
      "Traceback (most recent call last):\n",
      "  File \"C:\\Users\\JABIR\\AppData\\Roaming\\Python\\Python38\\site-packages\\telegram\\ext\\updater.py\", line 646, in _network_loop_retry\n",
      "    if not action_cb():\n",
      "  File \"C:\\Users\\JABIR\\AppData\\Roaming\\Python\\Python38\\site-packages\\telegram\\ext\\updater.py\", line 597, in polling_action_cb\n",
      "    updates = self.bot.get_updates(\n",
      "  File \"C:\\Users\\JABIR\\AppData\\Roaming\\Python\\Python38\\site-packages\\telegram\\ext\\extbot.py\", line 222, in get_updates\n",
      "    updates = super().get_updates(\n",
      "  File \"C:\\Users\\JABIR\\AppData\\Roaming\\Python\\Python38\\site-packages\\telegram\\bot.py\", line 130, in decorator\n",
      "    result = func(*args, **kwargs)\n",
      "  File \"C:\\Users\\JABIR\\AppData\\Roaming\\Python\\Python38\\site-packages\\telegram\\bot.py\", line 2861, in get_updates\n",
      "    self._post(\n",
      "  File \"C:\\Users\\JABIR\\AppData\\Roaming\\Python\\Python38\\site-packages\\telegram\\bot.py\", line 295, in _post\n",
      "    return self.request.post(\n",
      "  File \"C:\\Users\\JABIR\\AppData\\Roaming\\Python\\Python38\\site-packages\\telegram\\utils\\request.py\", line 356, in post\n",
      "    result = self._request_wrapper(\n",
      "  File \"C:\\Users\\JABIR\\AppData\\Roaming\\Python\\Python38\\site-packages\\telegram\\utils\\request.py\", line 283, in _request_wrapper\n",
      "    raise Conflict(message)\n",
      "telegram.error.Conflict: Conflict: terminated by other getUpdates request; make sure that only one bot instance is running\n"
     ]
    },
    {
     "name": "stderr",
     "output_type": "stream",
     "text": [
      "Error while getting Updates: Conflict: terminated by other getUpdates request; make sure that only one bot instance is running\n",
      "No error handlers are registered, logging exception.\n",
      "Traceback (most recent call last):\n",
      "  File \"C:\\Users\\JABIR\\AppData\\Roaming\\Python\\Python38\\site-packages\\telegram\\ext\\updater.py\", line 646, in _network_loop_retry\n",
      "    if not action_cb():\n",
      "  File \"C:\\Users\\JABIR\\AppData\\Roaming\\Python\\Python38\\site-packages\\telegram\\ext\\updater.py\", line 597, in polling_action_cb\n",
      "    updates = self.bot.get_updates(\n",
      "  File \"C:\\Users\\JABIR\\AppData\\Roaming\\Python\\Python38\\site-packages\\telegram\\ext\\extbot.py\", line 222, in get_updates\n",
      "    updates = super().get_updates(\n",
      "  File \"C:\\Users\\JABIR\\AppData\\Roaming\\Python\\Python38\\site-packages\\telegram\\bot.py\", line 130, in decorator\n",
      "    result = func(*args, **kwargs)\n",
      "  File \"C:\\Users\\JABIR\\AppData\\Roaming\\Python\\Python38\\site-packages\\telegram\\bot.py\", line 2861, in get_updates\n",
      "    self._post(\n",
      "  File \"C:\\Users\\JABIR\\AppData\\Roaming\\Python\\Python38\\site-packages\\telegram\\bot.py\", line 295, in _post\n",
      "    return self.request.post(\n",
      "  File \"C:\\Users\\JABIR\\AppData\\Roaming\\Python\\Python38\\site-packages\\telegram\\utils\\request.py\", line 356, in post\n",
      "    result = self._request_wrapper(\n",
      "  File \"C:\\Users\\JABIR\\AppData\\Roaming\\Python\\Python38\\site-packages\\telegram\\utils\\request.py\", line 283, in _request_wrapper\n",
      "    raise Conflict(message)\n",
      "telegram.error.Conflict: Conflict: terminated by other getUpdates request; make sure that only one bot instance is running\n",
      "Error while getting Updates: Conflict: terminated by other getUpdates request; make sure that only one bot instance is running\n",
      "No error handlers are registered, logging exception.\n",
      "Traceback (most recent call last):\n",
      "  File \"C:\\Users\\JABIR\\AppData\\Roaming\\Python\\Python38\\site-packages\\telegram\\ext\\updater.py\", line 646, in _network_loop_retry\n",
      "    if not action_cb():\n",
      "  File \"C:\\Users\\JABIR\\AppData\\Roaming\\Python\\Python38\\site-packages\\telegram\\ext\\updater.py\", line 597, in polling_action_cb\n",
      "    updates = self.bot.get_updates(\n",
      "  File \"C:\\Users\\JABIR\\AppData\\Roaming\\Python\\Python38\\site-packages\\telegram\\ext\\extbot.py\", line 222, in get_updates\n",
      "    updates = super().get_updates(\n",
      "  File \"C:\\Users\\JABIR\\AppData\\Roaming\\Python\\Python38\\site-packages\\telegram\\bot.py\", line 130, in decorator\n",
      "    result = func(*args, **kwargs)\n",
      "  File \"C:\\Users\\JABIR\\AppData\\Roaming\\Python\\Python38\\site-packages\\telegram\\bot.py\", line 2861, in get_updates\n",
      "    self._post(\n",
      "  File \"C:\\Users\\JABIR\\AppData\\Roaming\\Python\\Python38\\site-packages\\telegram\\bot.py\", line 295, in _post\n",
      "    return self.request.post(\n",
      "  File \"C:\\Users\\JABIR\\AppData\\Roaming\\Python\\Python38\\site-packages\\telegram\\utils\\request.py\", line 356, in post\n",
      "    result = self._request_wrapper(\n",
      "  File \"C:\\Users\\JABIR\\AppData\\Roaming\\Python\\Python38\\site-packages\\telegram\\utils\\request.py\", line 283, in _request_wrapper\n",
      "    raise Conflict(message)\n",
      "telegram.error.Conflict: Conflict: terminated by other getUpdates request; make sure that only one bot instance is running\n",
      "Error while getting Updates: Conflict: terminated by other getUpdates request; make sure that only one bot instance is running\n",
      "No error handlers are registered, logging exception.\n",
      "Traceback (most recent call last):\n",
      "  File \"C:\\Users\\JABIR\\AppData\\Roaming\\Python\\Python38\\site-packages\\telegram\\ext\\updater.py\", line 646, in _network_loop_retry\n",
      "    if not action_cb():\n",
      "  File \"C:\\Users\\JABIR\\AppData\\Roaming\\Python\\Python38\\site-packages\\telegram\\ext\\updater.py\", line 597, in polling_action_cb\n",
      "    updates = self.bot.get_updates(\n",
      "  File \"C:\\Users\\JABIR\\AppData\\Roaming\\Python\\Python38\\site-packages\\telegram\\ext\\extbot.py\", line 222, in get_updates\n",
      "    updates = super().get_updates(\n",
      "  File \"C:\\Users\\JABIR\\AppData\\Roaming\\Python\\Python38\\site-packages\\telegram\\bot.py\", line 130, in decorator\n",
      "    result = func(*args, **kwargs)\n",
      "  File \"C:\\Users\\JABIR\\AppData\\Roaming\\Python\\Python38\\site-packages\\telegram\\bot.py\", line 2861, in get_updates\n",
      "    self._post(\n",
      "  File \"C:\\Users\\JABIR\\AppData\\Roaming\\Python\\Python38\\site-packages\\telegram\\bot.py\", line 295, in _post\n",
      "    return self.request.post(\n",
      "  File \"C:\\Users\\JABIR\\AppData\\Roaming\\Python\\Python38\\site-packages\\telegram\\utils\\request.py\", line 356, in post\n",
      "    result = self._request_wrapper(\n",
      "  File \"C:\\Users\\JABIR\\AppData\\Roaming\\Python\\Python38\\site-packages\\telegram\\utils\\request.py\", line 283, in _request_wrapper\n",
      "    raise Conflict(message)\n",
      "telegram.error.Conflict: Conflict: terminated by other getUpdates request; make sure that only one bot instance is running\n",
      "Error while getting Updates: Conflict: terminated by other getUpdates request; make sure that only one bot instance is running\n",
      "No error handlers are registered, logging exception.\n",
      "Traceback (most recent call last):\n",
      "  File \"C:\\Users\\JABIR\\AppData\\Roaming\\Python\\Python38\\site-packages\\telegram\\ext\\updater.py\", line 646, in _network_loop_retry\n",
      "    if not action_cb():\n",
      "  File \"C:\\Users\\JABIR\\AppData\\Roaming\\Python\\Python38\\site-packages\\telegram\\ext\\updater.py\", line 597, in polling_action_cb\n",
      "    updates = self.bot.get_updates(\n",
      "  File \"C:\\Users\\JABIR\\AppData\\Roaming\\Python\\Python38\\site-packages\\telegram\\ext\\extbot.py\", line 222, in get_updates\n",
      "    updates = super().get_updates(\n",
      "  File \"C:\\Users\\JABIR\\AppData\\Roaming\\Python\\Python38\\site-packages\\telegram\\bot.py\", line 130, in decorator\n",
      "    result = func(*args, **kwargs)\n",
      "  File \"C:\\Users\\JABIR\\AppData\\Roaming\\Python\\Python38\\site-packages\\telegram\\bot.py\", line 2861, in get_updates\n",
      "    self._post(\n",
      "  File \"C:\\Users\\JABIR\\AppData\\Roaming\\Python\\Python38\\site-packages\\telegram\\bot.py\", line 295, in _post\n",
      "    return self.request.post(\n",
      "  File \"C:\\Users\\JABIR\\AppData\\Roaming\\Python\\Python38\\site-packages\\telegram\\utils\\request.py\", line 356, in post\n",
      "    result = self._request_wrapper(\n",
      "  File \"C:\\Users\\JABIR\\AppData\\Roaming\\Python\\Python38\\site-packages\\telegram\\utils\\request.py\", line 283, in _request_wrapper\n",
      "    raise Conflict(message)\n",
      "telegram.error.Conflict: Conflict: terminated by other getUpdates request; make sure that only one bot instance is running\n",
      "Error while getting Updates: Conflict: terminated by other getUpdates request; make sure that only one bot instance is running\n",
      "No error handlers are registered, logging exception.\n",
      "Traceback (most recent call last):\n",
      "  File \"C:\\Users\\JABIR\\AppData\\Roaming\\Python\\Python38\\site-packages\\telegram\\ext\\updater.py\", line 646, in _network_loop_retry\n",
      "    if not action_cb():\n",
      "  File \"C:\\Users\\JABIR\\AppData\\Roaming\\Python\\Python38\\site-packages\\telegram\\ext\\updater.py\", line 597, in polling_action_cb\n",
      "    updates = self.bot.get_updates(\n",
      "  File \"C:\\Users\\JABIR\\AppData\\Roaming\\Python\\Python38\\site-packages\\telegram\\ext\\extbot.py\", line 222, in get_updates\n",
      "    updates = super().get_updates(\n",
      "  File \"C:\\Users\\JABIR\\AppData\\Roaming\\Python\\Python38\\site-packages\\telegram\\bot.py\", line 130, in decorator\n",
      "    result = func(*args, **kwargs)\n",
      "  File \"C:\\Users\\JABIR\\AppData\\Roaming\\Python\\Python38\\site-packages\\telegram\\bot.py\", line 2861, in get_updates\n",
      "    self._post(\n",
      "  File \"C:\\Users\\JABIR\\AppData\\Roaming\\Python\\Python38\\site-packages\\telegram\\bot.py\", line 295, in _post\n",
      "    return self.request.post(\n",
      "  File \"C:\\Users\\JABIR\\AppData\\Roaming\\Python\\Python38\\site-packages\\telegram\\utils\\request.py\", line 356, in post\n",
      "    result = self._request_wrapper(\n",
      "  File \"C:\\Users\\JABIR\\AppData\\Roaming\\Python\\Python38\\site-packages\\telegram\\utils\\request.py\", line 283, in _request_wrapper\n",
      "    raise Conflict(message)\n",
      "telegram.error.Conflict: Conflict: terminated by other getUpdates request; make sure that only one bot instance is running\n",
      "Error while getting Updates: Conflict: terminated by other getUpdates request; make sure that only one bot instance is running\n",
      "No error handlers are registered, logging exception.\n",
      "Traceback (most recent call last):\n",
      "  File \"C:\\Users\\JABIR\\AppData\\Roaming\\Python\\Python38\\site-packages\\telegram\\ext\\updater.py\", line 646, in _network_loop_retry\n",
      "    if not action_cb():\n",
      "  File \"C:\\Users\\JABIR\\AppData\\Roaming\\Python\\Python38\\site-packages\\telegram\\ext\\updater.py\", line 597, in polling_action_cb\n",
      "    updates = self.bot.get_updates(\n",
      "  File \"C:\\Users\\JABIR\\AppData\\Roaming\\Python\\Python38\\site-packages\\telegram\\ext\\extbot.py\", line 222, in get_updates\n",
      "    updates = super().get_updates(\n",
      "  File \"C:\\Users\\JABIR\\AppData\\Roaming\\Python\\Python38\\site-packages\\telegram\\bot.py\", line 130, in decorator\n",
      "    result = func(*args, **kwargs)\n",
      "  File \"C:\\Users\\JABIR\\AppData\\Roaming\\Python\\Python38\\site-packages\\telegram\\bot.py\", line 2861, in get_updates\n",
      "    self._post(\n",
      "  File \"C:\\Users\\JABIR\\AppData\\Roaming\\Python\\Python38\\site-packages\\telegram\\bot.py\", line 295, in _post\n",
      "    return self.request.post(\n",
      "  File \"C:\\Users\\JABIR\\AppData\\Roaming\\Python\\Python38\\site-packages\\telegram\\utils\\request.py\", line 356, in post\n",
      "    result = self._request_wrapper(\n",
      "  File \"C:\\Users\\JABIR\\AppData\\Roaming\\Python\\Python38\\site-packages\\telegram\\utils\\request.py\", line 283, in _request_wrapper\n",
      "    raise Conflict(message)\n",
      "telegram.error.Conflict: Conflict: terminated by other getUpdates request; make sure that only one bot instance is running\n"
     ]
    },
    {
     "name": "stderr",
     "output_type": "stream",
     "text": [
      "Error while getting Updates: Conflict: terminated by other getUpdates request; make sure that only one bot instance is running\n",
      "No error handlers are registered, logging exception.\n",
      "Traceback (most recent call last):\n",
      "  File \"C:\\Users\\JABIR\\AppData\\Roaming\\Python\\Python38\\site-packages\\telegram\\ext\\updater.py\", line 646, in _network_loop_retry\n",
      "    if not action_cb():\n",
      "  File \"C:\\Users\\JABIR\\AppData\\Roaming\\Python\\Python38\\site-packages\\telegram\\ext\\updater.py\", line 597, in polling_action_cb\n",
      "    updates = self.bot.get_updates(\n",
      "  File \"C:\\Users\\JABIR\\AppData\\Roaming\\Python\\Python38\\site-packages\\telegram\\ext\\extbot.py\", line 222, in get_updates\n",
      "    updates = super().get_updates(\n",
      "  File \"C:\\Users\\JABIR\\AppData\\Roaming\\Python\\Python38\\site-packages\\telegram\\bot.py\", line 130, in decorator\n",
      "    result = func(*args, **kwargs)\n",
      "  File \"C:\\Users\\JABIR\\AppData\\Roaming\\Python\\Python38\\site-packages\\telegram\\bot.py\", line 2861, in get_updates\n",
      "    self._post(\n",
      "  File \"C:\\Users\\JABIR\\AppData\\Roaming\\Python\\Python38\\site-packages\\telegram\\bot.py\", line 295, in _post\n",
      "    return self.request.post(\n",
      "  File \"C:\\Users\\JABIR\\AppData\\Roaming\\Python\\Python38\\site-packages\\telegram\\utils\\request.py\", line 356, in post\n",
      "    result = self._request_wrapper(\n",
      "  File \"C:\\Users\\JABIR\\AppData\\Roaming\\Python\\Python38\\site-packages\\telegram\\utils\\request.py\", line 283, in _request_wrapper\n",
      "    raise Conflict(message)\n",
      "telegram.error.Conflict: Conflict: terminated by other getUpdates request; make sure that only one bot instance is running\n",
      "Error while getting Updates: Conflict: terminated by other getUpdates request; make sure that only one bot instance is running\n",
      "No error handlers are registered, logging exception.\n",
      "Traceback (most recent call last):\n",
      "  File \"C:\\Users\\JABIR\\AppData\\Roaming\\Python\\Python38\\site-packages\\telegram\\ext\\updater.py\", line 646, in _network_loop_retry\n",
      "    if not action_cb():\n",
      "  File \"C:\\Users\\JABIR\\AppData\\Roaming\\Python\\Python38\\site-packages\\telegram\\ext\\updater.py\", line 597, in polling_action_cb\n",
      "    updates = self.bot.get_updates(\n",
      "  File \"C:\\Users\\JABIR\\AppData\\Roaming\\Python\\Python38\\site-packages\\telegram\\ext\\extbot.py\", line 222, in get_updates\n",
      "    updates = super().get_updates(\n",
      "  File \"C:\\Users\\JABIR\\AppData\\Roaming\\Python\\Python38\\site-packages\\telegram\\bot.py\", line 130, in decorator\n",
      "    result = func(*args, **kwargs)\n",
      "  File \"C:\\Users\\JABIR\\AppData\\Roaming\\Python\\Python38\\site-packages\\telegram\\bot.py\", line 2861, in get_updates\n",
      "    self._post(\n",
      "  File \"C:\\Users\\JABIR\\AppData\\Roaming\\Python\\Python38\\site-packages\\telegram\\bot.py\", line 295, in _post\n",
      "    return self.request.post(\n",
      "  File \"C:\\Users\\JABIR\\AppData\\Roaming\\Python\\Python38\\site-packages\\telegram\\utils\\request.py\", line 356, in post\n",
      "    result = self._request_wrapper(\n",
      "  File \"C:\\Users\\JABIR\\AppData\\Roaming\\Python\\Python38\\site-packages\\telegram\\utils\\request.py\", line 283, in _request_wrapper\n",
      "    raise Conflict(message)\n",
      "telegram.error.Conflict: Conflict: terminated by other getUpdates request; make sure that only one bot instance is running\n",
      "Error while getting Updates: Conflict: terminated by other getUpdates request; make sure that only one bot instance is running\n",
      "No error handlers are registered, logging exception.\n",
      "Traceback (most recent call last):\n",
      "  File \"C:\\Users\\JABIR\\AppData\\Roaming\\Python\\Python38\\site-packages\\telegram\\ext\\updater.py\", line 646, in _network_loop_retry\n",
      "    if not action_cb():\n",
      "  File \"C:\\Users\\JABIR\\AppData\\Roaming\\Python\\Python38\\site-packages\\telegram\\ext\\updater.py\", line 597, in polling_action_cb\n",
      "    updates = self.bot.get_updates(\n",
      "  File \"C:\\Users\\JABIR\\AppData\\Roaming\\Python\\Python38\\site-packages\\telegram\\ext\\extbot.py\", line 222, in get_updates\n",
      "    updates = super().get_updates(\n",
      "  File \"C:\\Users\\JABIR\\AppData\\Roaming\\Python\\Python38\\site-packages\\telegram\\bot.py\", line 130, in decorator\n",
      "    result = func(*args, **kwargs)\n",
      "  File \"C:\\Users\\JABIR\\AppData\\Roaming\\Python\\Python38\\site-packages\\telegram\\bot.py\", line 2861, in get_updates\n",
      "    self._post(\n",
      "  File \"C:\\Users\\JABIR\\AppData\\Roaming\\Python\\Python38\\site-packages\\telegram\\bot.py\", line 295, in _post\n",
      "    return self.request.post(\n",
      "  File \"C:\\Users\\JABIR\\AppData\\Roaming\\Python\\Python38\\site-packages\\telegram\\utils\\request.py\", line 356, in post\n",
      "    result = self._request_wrapper(\n",
      "  File \"C:\\Users\\JABIR\\AppData\\Roaming\\Python\\Python38\\site-packages\\telegram\\utils\\request.py\", line 283, in _request_wrapper\n",
      "    raise Conflict(message)\n",
      "telegram.error.Conflict: Conflict: terminated by other getUpdates request; make sure that only one bot instance is running\n",
      "Error while getting Updates: Conflict: terminated by other getUpdates request; make sure that only one bot instance is running\n",
      "No error handlers are registered, logging exception.\n",
      "Traceback (most recent call last):\n",
      "  File \"C:\\Users\\JABIR\\AppData\\Roaming\\Python\\Python38\\site-packages\\telegram\\ext\\updater.py\", line 646, in _network_loop_retry\n",
      "    if not action_cb():\n",
      "  File \"C:\\Users\\JABIR\\AppData\\Roaming\\Python\\Python38\\site-packages\\telegram\\ext\\updater.py\", line 597, in polling_action_cb\n",
      "    updates = self.bot.get_updates(\n",
      "  File \"C:\\Users\\JABIR\\AppData\\Roaming\\Python\\Python38\\site-packages\\telegram\\ext\\extbot.py\", line 222, in get_updates\n",
      "    updates = super().get_updates(\n",
      "  File \"C:\\Users\\JABIR\\AppData\\Roaming\\Python\\Python38\\site-packages\\telegram\\bot.py\", line 130, in decorator\n",
      "    result = func(*args, **kwargs)\n",
      "  File \"C:\\Users\\JABIR\\AppData\\Roaming\\Python\\Python38\\site-packages\\telegram\\bot.py\", line 2861, in get_updates\n",
      "    self._post(\n",
      "  File \"C:\\Users\\JABIR\\AppData\\Roaming\\Python\\Python38\\site-packages\\telegram\\bot.py\", line 295, in _post\n",
      "    return self.request.post(\n",
      "  File \"C:\\Users\\JABIR\\AppData\\Roaming\\Python\\Python38\\site-packages\\telegram\\utils\\request.py\", line 356, in post\n",
      "    result = self._request_wrapper(\n",
      "  File \"C:\\Users\\JABIR\\AppData\\Roaming\\Python\\Python38\\site-packages\\telegram\\utils\\request.py\", line 283, in _request_wrapper\n",
      "    raise Conflict(message)\n",
      "telegram.error.Conflict: Conflict: terminated by other getUpdates request; make sure that only one bot instance is running\n",
      "Error while getting Updates: Conflict: terminated by other getUpdates request; make sure that only one bot instance is running\n",
      "No error handlers are registered, logging exception.\n",
      "Traceback (most recent call last):\n",
      "  File \"C:\\Users\\JABIR\\AppData\\Roaming\\Python\\Python38\\site-packages\\telegram\\ext\\updater.py\", line 646, in _network_loop_retry\n",
      "    if not action_cb():\n",
      "  File \"C:\\Users\\JABIR\\AppData\\Roaming\\Python\\Python38\\site-packages\\telegram\\ext\\updater.py\", line 597, in polling_action_cb\n",
      "    updates = self.bot.get_updates(\n",
      "  File \"C:\\Users\\JABIR\\AppData\\Roaming\\Python\\Python38\\site-packages\\telegram\\ext\\extbot.py\", line 222, in get_updates\n",
      "    updates = super().get_updates(\n",
      "  File \"C:\\Users\\JABIR\\AppData\\Roaming\\Python\\Python38\\site-packages\\telegram\\bot.py\", line 130, in decorator\n",
      "    result = func(*args, **kwargs)\n",
      "  File \"C:\\Users\\JABIR\\AppData\\Roaming\\Python\\Python38\\site-packages\\telegram\\bot.py\", line 2861, in get_updates\n",
      "    self._post(\n",
      "  File \"C:\\Users\\JABIR\\AppData\\Roaming\\Python\\Python38\\site-packages\\telegram\\bot.py\", line 295, in _post\n",
      "    return self.request.post(\n",
      "  File \"C:\\Users\\JABIR\\AppData\\Roaming\\Python\\Python38\\site-packages\\telegram\\utils\\request.py\", line 356, in post\n",
      "    result = self._request_wrapper(\n",
      "  File \"C:\\Users\\JABIR\\AppData\\Roaming\\Python\\Python38\\site-packages\\telegram\\utils\\request.py\", line 283, in _request_wrapper\n",
      "    raise Conflict(message)\n",
      "telegram.error.Conflict: Conflict: terminated by other getUpdates request; make sure that only one bot instance is running\n",
      "Error while getting Updates: Conflict: terminated by other getUpdates request; make sure that only one bot instance is running\n",
      "No error handlers are registered, logging exception.\n",
      "Traceback (most recent call last):\n",
      "  File \"C:\\Users\\JABIR\\AppData\\Roaming\\Python\\Python38\\site-packages\\telegram\\ext\\updater.py\", line 646, in _network_loop_retry\n",
      "    if not action_cb():\n",
      "  File \"C:\\Users\\JABIR\\AppData\\Roaming\\Python\\Python38\\site-packages\\telegram\\ext\\updater.py\", line 597, in polling_action_cb\n",
      "    updates = self.bot.get_updates(\n",
      "  File \"C:\\Users\\JABIR\\AppData\\Roaming\\Python\\Python38\\site-packages\\telegram\\ext\\extbot.py\", line 222, in get_updates\n",
      "    updates = super().get_updates(\n",
      "  File \"C:\\Users\\JABIR\\AppData\\Roaming\\Python\\Python38\\site-packages\\telegram\\bot.py\", line 130, in decorator\n",
      "    result = func(*args, **kwargs)\n",
      "  File \"C:\\Users\\JABIR\\AppData\\Roaming\\Python\\Python38\\site-packages\\telegram\\bot.py\", line 2861, in get_updates\n",
      "    self._post(\n",
      "  File \"C:\\Users\\JABIR\\AppData\\Roaming\\Python\\Python38\\site-packages\\telegram\\bot.py\", line 295, in _post\n",
      "    return self.request.post(\n",
      "  File \"C:\\Users\\JABIR\\AppData\\Roaming\\Python\\Python38\\site-packages\\telegram\\utils\\request.py\", line 356, in post\n",
      "    result = self._request_wrapper(\n",
      "  File \"C:\\Users\\JABIR\\AppData\\Roaming\\Python\\Python38\\site-packages\\telegram\\utils\\request.py\", line 283, in _request_wrapper\n",
      "    raise Conflict(message)\n",
      "telegram.error.Conflict: Conflict: terminated by other getUpdates request; make sure that only one bot instance is running\n"
     ]
    },
    {
     "name": "stderr",
     "output_type": "stream",
     "text": [
      "Error while getting Updates: Conflict: terminated by other getUpdates request; make sure that only one bot instance is running\n",
      "No error handlers are registered, logging exception.\n",
      "Traceback (most recent call last):\n",
      "  File \"C:\\Users\\JABIR\\AppData\\Roaming\\Python\\Python38\\site-packages\\telegram\\ext\\updater.py\", line 646, in _network_loop_retry\n",
      "    if not action_cb():\n",
      "  File \"C:\\Users\\JABIR\\AppData\\Roaming\\Python\\Python38\\site-packages\\telegram\\ext\\updater.py\", line 597, in polling_action_cb\n",
      "    updates = self.bot.get_updates(\n",
      "  File \"C:\\Users\\JABIR\\AppData\\Roaming\\Python\\Python38\\site-packages\\telegram\\ext\\extbot.py\", line 222, in get_updates\n",
      "    updates = super().get_updates(\n",
      "  File \"C:\\Users\\JABIR\\AppData\\Roaming\\Python\\Python38\\site-packages\\telegram\\bot.py\", line 130, in decorator\n",
      "    result = func(*args, **kwargs)\n",
      "  File \"C:\\Users\\JABIR\\AppData\\Roaming\\Python\\Python38\\site-packages\\telegram\\bot.py\", line 2861, in get_updates\n",
      "    self._post(\n",
      "  File \"C:\\Users\\JABIR\\AppData\\Roaming\\Python\\Python38\\site-packages\\telegram\\bot.py\", line 295, in _post\n",
      "    return self.request.post(\n",
      "  File \"C:\\Users\\JABIR\\AppData\\Roaming\\Python\\Python38\\site-packages\\telegram\\utils\\request.py\", line 356, in post\n",
      "    result = self._request_wrapper(\n",
      "  File \"C:\\Users\\JABIR\\AppData\\Roaming\\Python\\Python38\\site-packages\\telegram\\utils\\request.py\", line 283, in _request_wrapper\n",
      "    raise Conflict(message)\n",
      "telegram.error.Conflict: Conflict: terminated by other getUpdates request; make sure that only one bot instance is running\n",
      "Error while getting Updates: Conflict: terminated by other getUpdates request; make sure that only one bot instance is running\n",
      "No error handlers are registered, logging exception.\n",
      "Traceback (most recent call last):\n",
      "  File \"C:\\Users\\JABIR\\AppData\\Roaming\\Python\\Python38\\site-packages\\telegram\\ext\\updater.py\", line 646, in _network_loop_retry\n",
      "    if not action_cb():\n",
      "  File \"C:\\Users\\JABIR\\AppData\\Roaming\\Python\\Python38\\site-packages\\telegram\\ext\\updater.py\", line 597, in polling_action_cb\n",
      "    updates = self.bot.get_updates(\n",
      "  File \"C:\\Users\\JABIR\\AppData\\Roaming\\Python\\Python38\\site-packages\\telegram\\ext\\extbot.py\", line 222, in get_updates\n",
      "    updates = super().get_updates(\n",
      "  File \"C:\\Users\\JABIR\\AppData\\Roaming\\Python\\Python38\\site-packages\\telegram\\bot.py\", line 130, in decorator\n",
      "    result = func(*args, **kwargs)\n",
      "  File \"C:\\Users\\JABIR\\AppData\\Roaming\\Python\\Python38\\site-packages\\telegram\\bot.py\", line 2861, in get_updates\n",
      "    self._post(\n",
      "  File \"C:\\Users\\JABIR\\AppData\\Roaming\\Python\\Python38\\site-packages\\telegram\\bot.py\", line 295, in _post\n",
      "    return self.request.post(\n",
      "  File \"C:\\Users\\JABIR\\AppData\\Roaming\\Python\\Python38\\site-packages\\telegram\\utils\\request.py\", line 356, in post\n",
      "    result = self._request_wrapper(\n",
      "  File \"C:\\Users\\JABIR\\AppData\\Roaming\\Python\\Python38\\site-packages\\telegram\\utils\\request.py\", line 283, in _request_wrapper\n",
      "    raise Conflict(message)\n",
      "telegram.error.Conflict: Conflict: terminated by other getUpdates request; make sure that only one bot instance is running\n",
      "Error while getting Updates: Conflict: terminated by other getUpdates request; make sure that only one bot instance is running\n",
      "No error handlers are registered, logging exception.\n",
      "Traceback (most recent call last):\n",
      "  File \"C:\\Users\\JABIR\\AppData\\Roaming\\Python\\Python38\\site-packages\\telegram\\ext\\updater.py\", line 646, in _network_loop_retry\n",
      "    if not action_cb():\n",
      "  File \"C:\\Users\\JABIR\\AppData\\Roaming\\Python\\Python38\\site-packages\\telegram\\ext\\updater.py\", line 597, in polling_action_cb\n",
      "    updates = self.bot.get_updates(\n",
      "  File \"C:\\Users\\JABIR\\AppData\\Roaming\\Python\\Python38\\site-packages\\telegram\\ext\\extbot.py\", line 222, in get_updates\n",
      "    updates = super().get_updates(\n",
      "  File \"C:\\Users\\JABIR\\AppData\\Roaming\\Python\\Python38\\site-packages\\telegram\\bot.py\", line 130, in decorator\n",
      "    result = func(*args, **kwargs)\n",
      "  File \"C:\\Users\\JABIR\\AppData\\Roaming\\Python\\Python38\\site-packages\\telegram\\bot.py\", line 2861, in get_updates\n",
      "    self._post(\n",
      "  File \"C:\\Users\\JABIR\\AppData\\Roaming\\Python\\Python38\\site-packages\\telegram\\bot.py\", line 295, in _post\n",
      "    return self.request.post(\n",
      "  File \"C:\\Users\\JABIR\\AppData\\Roaming\\Python\\Python38\\site-packages\\telegram\\utils\\request.py\", line 356, in post\n",
      "    result = self._request_wrapper(\n",
      "  File \"C:\\Users\\JABIR\\AppData\\Roaming\\Python\\Python38\\site-packages\\telegram\\utils\\request.py\", line 283, in _request_wrapper\n",
      "    raise Conflict(message)\n",
      "telegram.error.Conflict: Conflict: terminated by other getUpdates request; make sure that only one bot instance is running\n",
      "Error while getting Updates: Conflict: terminated by other getUpdates request; make sure that only one bot instance is running\n",
      "No error handlers are registered, logging exception.\n",
      "Traceback (most recent call last):\n",
      "  File \"C:\\Users\\JABIR\\AppData\\Roaming\\Python\\Python38\\site-packages\\telegram\\ext\\updater.py\", line 646, in _network_loop_retry\n",
      "    if not action_cb():\n",
      "  File \"C:\\Users\\JABIR\\AppData\\Roaming\\Python\\Python38\\site-packages\\telegram\\ext\\updater.py\", line 597, in polling_action_cb\n",
      "    updates = self.bot.get_updates(\n",
      "  File \"C:\\Users\\JABIR\\AppData\\Roaming\\Python\\Python38\\site-packages\\telegram\\ext\\extbot.py\", line 222, in get_updates\n",
      "    updates = super().get_updates(\n",
      "  File \"C:\\Users\\JABIR\\AppData\\Roaming\\Python\\Python38\\site-packages\\telegram\\bot.py\", line 130, in decorator\n",
      "    result = func(*args, **kwargs)\n",
      "  File \"C:\\Users\\JABIR\\AppData\\Roaming\\Python\\Python38\\site-packages\\telegram\\bot.py\", line 2861, in get_updates\n",
      "    self._post(\n",
      "  File \"C:\\Users\\JABIR\\AppData\\Roaming\\Python\\Python38\\site-packages\\telegram\\bot.py\", line 295, in _post\n",
      "    return self.request.post(\n",
      "  File \"C:\\Users\\JABIR\\AppData\\Roaming\\Python\\Python38\\site-packages\\telegram\\utils\\request.py\", line 356, in post\n",
      "    result = self._request_wrapper(\n",
      "  File \"C:\\Users\\JABIR\\AppData\\Roaming\\Python\\Python38\\site-packages\\telegram\\utils\\request.py\", line 283, in _request_wrapper\n",
      "    raise Conflict(message)\n",
      "telegram.error.Conflict: Conflict: terminated by other getUpdates request; make sure that only one bot instance is running\n",
      "Error while getting Updates: Conflict: terminated by other getUpdates request; make sure that only one bot instance is running\n",
      "No error handlers are registered, logging exception.\n",
      "Traceback (most recent call last):\n",
      "  File \"C:\\Users\\JABIR\\AppData\\Roaming\\Python\\Python38\\site-packages\\telegram\\ext\\updater.py\", line 646, in _network_loop_retry\n",
      "    if not action_cb():\n",
      "  File \"C:\\Users\\JABIR\\AppData\\Roaming\\Python\\Python38\\site-packages\\telegram\\ext\\updater.py\", line 597, in polling_action_cb\n",
      "    updates = self.bot.get_updates(\n",
      "  File \"C:\\Users\\JABIR\\AppData\\Roaming\\Python\\Python38\\site-packages\\telegram\\ext\\extbot.py\", line 222, in get_updates\n",
      "    updates = super().get_updates(\n",
      "  File \"C:\\Users\\JABIR\\AppData\\Roaming\\Python\\Python38\\site-packages\\telegram\\bot.py\", line 130, in decorator\n",
      "    result = func(*args, **kwargs)\n",
      "  File \"C:\\Users\\JABIR\\AppData\\Roaming\\Python\\Python38\\site-packages\\telegram\\bot.py\", line 2861, in get_updates\n",
      "    self._post(\n",
      "  File \"C:\\Users\\JABIR\\AppData\\Roaming\\Python\\Python38\\site-packages\\telegram\\bot.py\", line 295, in _post\n",
      "    return self.request.post(\n",
      "  File \"C:\\Users\\JABIR\\AppData\\Roaming\\Python\\Python38\\site-packages\\telegram\\utils\\request.py\", line 356, in post\n",
      "    result = self._request_wrapper(\n",
      "  File \"C:\\Users\\JABIR\\AppData\\Roaming\\Python\\Python38\\site-packages\\telegram\\utils\\request.py\", line 283, in _request_wrapper\n",
      "    raise Conflict(message)\n",
      "telegram.error.Conflict: Conflict: terminated by other getUpdates request; make sure that only one bot instance is running\n",
      "Error while getting Updates: Conflict: terminated by other getUpdates request; make sure that only one bot instance is running\n",
      "No error handlers are registered, logging exception.\n",
      "Traceback (most recent call last):\n",
      "  File \"C:\\Users\\JABIR\\AppData\\Roaming\\Python\\Python38\\site-packages\\telegram\\ext\\updater.py\", line 646, in _network_loop_retry\n",
      "    if not action_cb():\n",
      "  File \"C:\\Users\\JABIR\\AppData\\Roaming\\Python\\Python38\\site-packages\\telegram\\ext\\updater.py\", line 597, in polling_action_cb\n",
      "    updates = self.bot.get_updates(\n",
      "  File \"C:\\Users\\JABIR\\AppData\\Roaming\\Python\\Python38\\site-packages\\telegram\\ext\\extbot.py\", line 222, in get_updates\n",
      "    updates = super().get_updates(\n",
      "  File \"C:\\Users\\JABIR\\AppData\\Roaming\\Python\\Python38\\site-packages\\telegram\\bot.py\", line 130, in decorator\n",
      "    result = func(*args, **kwargs)\n",
      "  File \"C:\\Users\\JABIR\\AppData\\Roaming\\Python\\Python38\\site-packages\\telegram\\bot.py\", line 2861, in get_updates\n",
      "    self._post(\n",
      "  File \"C:\\Users\\JABIR\\AppData\\Roaming\\Python\\Python38\\site-packages\\telegram\\bot.py\", line 295, in _post\n",
      "    return self.request.post(\n",
      "  File \"C:\\Users\\JABIR\\AppData\\Roaming\\Python\\Python38\\site-packages\\telegram\\utils\\request.py\", line 356, in post\n",
      "    result = self._request_wrapper(\n",
      "  File \"C:\\Users\\JABIR\\AppData\\Roaming\\Python\\Python38\\site-packages\\telegram\\utils\\request.py\", line 283, in _request_wrapper\n",
      "    raise Conflict(message)\n",
      "telegram.error.Conflict: Conflict: terminated by other getUpdates request; make sure that only one bot instance is running\n"
     ]
    },
    {
     "name": "stderr",
     "output_type": "stream",
     "text": [
      "Error while getting Updates: Conflict: terminated by other getUpdates request; make sure that only one bot instance is running\n",
      "No error handlers are registered, logging exception.\n",
      "Traceback (most recent call last):\n",
      "  File \"C:\\Users\\JABIR\\AppData\\Roaming\\Python\\Python38\\site-packages\\telegram\\ext\\updater.py\", line 646, in _network_loop_retry\n",
      "    if not action_cb():\n",
      "  File \"C:\\Users\\JABIR\\AppData\\Roaming\\Python\\Python38\\site-packages\\telegram\\ext\\updater.py\", line 597, in polling_action_cb\n",
      "    updates = self.bot.get_updates(\n",
      "  File \"C:\\Users\\JABIR\\AppData\\Roaming\\Python\\Python38\\site-packages\\telegram\\ext\\extbot.py\", line 222, in get_updates\n",
      "    updates = super().get_updates(\n",
      "  File \"C:\\Users\\JABIR\\AppData\\Roaming\\Python\\Python38\\site-packages\\telegram\\bot.py\", line 130, in decorator\n",
      "    result = func(*args, **kwargs)\n",
      "  File \"C:\\Users\\JABIR\\AppData\\Roaming\\Python\\Python38\\site-packages\\telegram\\bot.py\", line 2861, in get_updates\n",
      "    self._post(\n",
      "  File \"C:\\Users\\JABIR\\AppData\\Roaming\\Python\\Python38\\site-packages\\telegram\\bot.py\", line 295, in _post\n",
      "    return self.request.post(\n",
      "  File \"C:\\Users\\JABIR\\AppData\\Roaming\\Python\\Python38\\site-packages\\telegram\\utils\\request.py\", line 356, in post\n",
      "    result = self._request_wrapper(\n",
      "  File \"C:\\Users\\JABIR\\AppData\\Roaming\\Python\\Python38\\site-packages\\telegram\\utils\\request.py\", line 283, in _request_wrapper\n",
      "    raise Conflict(message)\n",
      "telegram.error.Conflict: Conflict: terminated by other getUpdates request; make sure that only one bot instance is running\n",
      "Error while getting Updates: Conflict: terminated by other getUpdates request; make sure that only one bot instance is running\n",
      "No error handlers are registered, logging exception.\n",
      "Traceback (most recent call last):\n",
      "  File \"C:\\Users\\JABIR\\AppData\\Roaming\\Python\\Python38\\site-packages\\telegram\\ext\\updater.py\", line 646, in _network_loop_retry\n",
      "    if not action_cb():\n",
      "  File \"C:\\Users\\JABIR\\AppData\\Roaming\\Python\\Python38\\site-packages\\telegram\\ext\\updater.py\", line 597, in polling_action_cb\n",
      "    updates = self.bot.get_updates(\n",
      "  File \"C:\\Users\\JABIR\\AppData\\Roaming\\Python\\Python38\\site-packages\\telegram\\ext\\extbot.py\", line 222, in get_updates\n",
      "    updates = super().get_updates(\n",
      "  File \"C:\\Users\\JABIR\\AppData\\Roaming\\Python\\Python38\\site-packages\\telegram\\bot.py\", line 130, in decorator\n",
      "    result = func(*args, **kwargs)\n",
      "  File \"C:\\Users\\JABIR\\AppData\\Roaming\\Python\\Python38\\site-packages\\telegram\\bot.py\", line 2861, in get_updates\n",
      "    self._post(\n",
      "  File \"C:\\Users\\JABIR\\AppData\\Roaming\\Python\\Python38\\site-packages\\telegram\\bot.py\", line 295, in _post\n",
      "    return self.request.post(\n",
      "  File \"C:\\Users\\JABIR\\AppData\\Roaming\\Python\\Python38\\site-packages\\telegram\\utils\\request.py\", line 356, in post\n",
      "    result = self._request_wrapper(\n",
      "  File \"C:\\Users\\JABIR\\AppData\\Roaming\\Python\\Python38\\site-packages\\telegram\\utils\\request.py\", line 283, in _request_wrapper\n",
      "    raise Conflict(message)\n",
      "telegram.error.Conflict: Conflict: terminated by other getUpdates request; make sure that only one bot instance is running\n",
      "Error while getting Updates: Conflict: terminated by other getUpdates request; make sure that only one bot instance is running\n",
      "No error handlers are registered, logging exception.\n",
      "Traceback (most recent call last):\n",
      "  File \"C:\\Users\\JABIR\\AppData\\Roaming\\Python\\Python38\\site-packages\\telegram\\ext\\updater.py\", line 646, in _network_loop_retry\n",
      "    if not action_cb():\n",
      "  File \"C:\\Users\\JABIR\\AppData\\Roaming\\Python\\Python38\\site-packages\\telegram\\ext\\updater.py\", line 597, in polling_action_cb\n",
      "    updates = self.bot.get_updates(\n",
      "  File \"C:\\Users\\JABIR\\AppData\\Roaming\\Python\\Python38\\site-packages\\telegram\\ext\\extbot.py\", line 222, in get_updates\n",
      "    updates = super().get_updates(\n",
      "  File \"C:\\Users\\JABIR\\AppData\\Roaming\\Python\\Python38\\site-packages\\telegram\\bot.py\", line 130, in decorator\n",
      "    result = func(*args, **kwargs)\n",
      "  File \"C:\\Users\\JABIR\\AppData\\Roaming\\Python\\Python38\\site-packages\\telegram\\bot.py\", line 2861, in get_updates\n",
      "    self._post(\n",
      "  File \"C:\\Users\\JABIR\\AppData\\Roaming\\Python\\Python38\\site-packages\\telegram\\bot.py\", line 295, in _post\n",
      "    return self.request.post(\n",
      "  File \"C:\\Users\\JABIR\\AppData\\Roaming\\Python\\Python38\\site-packages\\telegram\\utils\\request.py\", line 356, in post\n",
      "    result = self._request_wrapper(\n",
      "  File \"C:\\Users\\JABIR\\AppData\\Roaming\\Python\\Python38\\site-packages\\telegram\\utils\\request.py\", line 283, in _request_wrapper\n",
      "    raise Conflict(message)\n",
      "telegram.error.Conflict: Conflict: terminated by other getUpdates request; make sure that only one bot instance is running\n",
      "Error while getting Updates: Conflict: terminated by other getUpdates request; make sure that only one bot instance is running\n",
      "No error handlers are registered, logging exception.\n",
      "Traceback (most recent call last):\n",
      "  File \"C:\\Users\\JABIR\\AppData\\Roaming\\Python\\Python38\\site-packages\\telegram\\ext\\updater.py\", line 646, in _network_loop_retry\n",
      "    if not action_cb():\n",
      "  File \"C:\\Users\\JABIR\\AppData\\Roaming\\Python\\Python38\\site-packages\\telegram\\ext\\updater.py\", line 597, in polling_action_cb\n",
      "    updates = self.bot.get_updates(\n",
      "  File \"C:\\Users\\JABIR\\AppData\\Roaming\\Python\\Python38\\site-packages\\telegram\\ext\\extbot.py\", line 222, in get_updates\n",
      "    updates = super().get_updates(\n",
      "  File \"C:\\Users\\JABIR\\AppData\\Roaming\\Python\\Python38\\site-packages\\telegram\\bot.py\", line 130, in decorator\n",
      "    result = func(*args, **kwargs)\n",
      "  File \"C:\\Users\\JABIR\\AppData\\Roaming\\Python\\Python38\\site-packages\\telegram\\bot.py\", line 2861, in get_updates\n",
      "    self._post(\n",
      "  File \"C:\\Users\\JABIR\\AppData\\Roaming\\Python\\Python38\\site-packages\\telegram\\bot.py\", line 295, in _post\n",
      "    return self.request.post(\n",
      "  File \"C:\\Users\\JABIR\\AppData\\Roaming\\Python\\Python38\\site-packages\\telegram\\utils\\request.py\", line 356, in post\n",
      "    result = self._request_wrapper(\n",
      "  File \"C:\\Users\\JABIR\\AppData\\Roaming\\Python\\Python38\\site-packages\\telegram\\utils\\request.py\", line 283, in _request_wrapper\n",
      "    raise Conflict(message)\n",
      "telegram.error.Conflict: Conflict: terminated by other getUpdates request; make sure that only one bot instance is running\n",
      "Error while getting Updates: Conflict: terminated by other getUpdates request; make sure that only one bot instance is running\n",
      "No error handlers are registered, logging exception.\n",
      "Traceback (most recent call last):\n",
      "  File \"C:\\Users\\JABIR\\AppData\\Roaming\\Python\\Python38\\site-packages\\telegram\\ext\\updater.py\", line 646, in _network_loop_retry\n",
      "    if not action_cb():\n",
      "  File \"C:\\Users\\JABIR\\AppData\\Roaming\\Python\\Python38\\site-packages\\telegram\\ext\\updater.py\", line 597, in polling_action_cb\n",
      "    updates = self.bot.get_updates(\n",
      "  File \"C:\\Users\\JABIR\\AppData\\Roaming\\Python\\Python38\\site-packages\\telegram\\ext\\extbot.py\", line 222, in get_updates\n",
      "    updates = super().get_updates(\n",
      "  File \"C:\\Users\\JABIR\\AppData\\Roaming\\Python\\Python38\\site-packages\\telegram\\bot.py\", line 130, in decorator\n",
      "    result = func(*args, **kwargs)\n",
      "  File \"C:\\Users\\JABIR\\AppData\\Roaming\\Python\\Python38\\site-packages\\telegram\\bot.py\", line 2861, in get_updates\n",
      "    self._post(\n",
      "  File \"C:\\Users\\JABIR\\AppData\\Roaming\\Python\\Python38\\site-packages\\telegram\\bot.py\", line 295, in _post\n",
      "    return self.request.post(\n",
      "  File \"C:\\Users\\JABIR\\AppData\\Roaming\\Python\\Python38\\site-packages\\telegram\\utils\\request.py\", line 356, in post\n",
      "    result = self._request_wrapper(\n",
      "  File \"C:\\Users\\JABIR\\AppData\\Roaming\\Python\\Python38\\site-packages\\telegram\\utils\\request.py\", line 283, in _request_wrapper\n",
      "    raise Conflict(message)\n",
      "telegram.error.Conflict: Conflict: terminated by other getUpdates request; make sure that only one bot instance is running\n",
      "Error while getting Updates: Conflict: terminated by other getUpdates request; make sure that only one bot instance is running\n",
      "No error handlers are registered, logging exception.\n",
      "Traceback (most recent call last):\n",
      "  File \"C:\\Users\\JABIR\\AppData\\Roaming\\Python\\Python38\\site-packages\\telegram\\ext\\updater.py\", line 646, in _network_loop_retry\n",
      "    if not action_cb():\n",
      "  File \"C:\\Users\\JABIR\\AppData\\Roaming\\Python\\Python38\\site-packages\\telegram\\ext\\updater.py\", line 597, in polling_action_cb\n",
      "    updates = self.bot.get_updates(\n",
      "  File \"C:\\Users\\JABIR\\AppData\\Roaming\\Python\\Python38\\site-packages\\telegram\\ext\\extbot.py\", line 222, in get_updates\n",
      "    updates = super().get_updates(\n",
      "  File \"C:\\Users\\JABIR\\AppData\\Roaming\\Python\\Python38\\site-packages\\telegram\\bot.py\", line 130, in decorator\n",
      "    result = func(*args, **kwargs)\n",
      "  File \"C:\\Users\\JABIR\\AppData\\Roaming\\Python\\Python38\\site-packages\\telegram\\bot.py\", line 2861, in get_updates\n",
      "    self._post(\n",
      "  File \"C:\\Users\\JABIR\\AppData\\Roaming\\Python\\Python38\\site-packages\\telegram\\bot.py\", line 295, in _post\n",
      "    return self.request.post(\n",
      "  File \"C:\\Users\\JABIR\\AppData\\Roaming\\Python\\Python38\\site-packages\\telegram\\utils\\request.py\", line 356, in post\n",
      "    result = self._request_wrapper(\n",
      "  File \"C:\\Users\\JABIR\\AppData\\Roaming\\Python\\Python38\\site-packages\\telegram\\utils\\request.py\", line 283, in _request_wrapper\n",
      "    raise Conflict(message)\n",
      "telegram.error.Conflict: Conflict: terminated by other getUpdates request; make sure that only one bot instance is running\n"
     ]
    },
    {
     "name": "stderr",
     "output_type": "stream",
     "text": [
      "Error while getting Updates: Conflict: terminated by other getUpdates request; make sure that only one bot instance is running\n",
      "No error handlers are registered, logging exception.\n",
      "Traceback (most recent call last):\n",
      "  File \"C:\\Users\\JABIR\\AppData\\Roaming\\Python\\Python38\\site-packages\\telegram\\ext\\updater.py\", line 646, in _network_loop_retry\n",
      "    if not action_cb():\n",
      "  File \"C:\\Users\\JABIR\\AppData\\Roaming\\Python\\Python38\\site-packages\\telegram\\ext\\updater.py\", line 597, in polling_action_cb\n",
      "    updates = self.bot.get_updates(\n",
      "  File \"C:\\Users\\JABIR\\AppData\\Roaming\\Python\\Python38\\site-packages\\telegram\\ext\\extbot.py\", line 222, in get_updates\n",
      "    updates = super().get_updates(\n",
      "  File \"C:\\Users\\JABIR\\AppData\\Roaming\\Python\\Python38\\site-packages\\telegram\\bot.py\", line 130, in decorator\n",
      "    result = func(*args, **kwargs)\n",
      "  File \"C:\\Users\\JABIR\\AppData\\Roaming\\Python\\Python38\\site-packages\\telegram\\bot.py\", line 2861, in get_updates\n",
      "    self._post(\n",
      "  File \"C:\\Users\\JABIR\\AppData\\Roaming\\Python\\Python38\\site-packages\\telegram\\bot.py\", line 295, in _post\n",
      "    return self.request.post(\n",
      "  File \"C:\\Users\\JABIR\\AppData\\Roaming\\Python\\Python38\\site-packages\\telegram\\utils\\request.py\", line 356, in post\n",
      "    result = self._request_wrapper(\n",
      "  File \"C:\\Users\\JABIR\\AppData\\Roaming\\Python\\Python38\\site-packages\\telegram\\utils\\request.py\", line 283, in _request_wrapper\n",
      "    raise Conflict(message)\n",
      "telegram.error.Conflict: Conflict: terminated by other getUpdates request; make sure that only one bot instance is running\n",
      "Error while getting Updates: Conflict: terminated by other getUpdates request; make sure that only one bot instance is running\n",
      "No error handlers are registered, logging exception.\n",
      "Traceback (most recent call last):\n",
      "  File \"C:\\Users\\JABIR\\AppData\\Roaming\\Python\\Python38\\site-packages\\telegram\\ext\\updater.py\", line 646, in _network_loop_retry\n",
      "    if not action_cb():\n",
      "  File \"C:\\Users\\JABIR\\AppData\\Roaming\\Python\\Python38\\site-packages\\telegram\\ext\\updater.py\", line 597, in polling_action_cb\n",
      "    updates = self.bot.get_updates(\n",
      "  File \"C:\\Users\\JABIR\\AppData\\Roaming\\Python\\Python38\\site-packages\\telegram\\ext\\extbot.py\", line 222, in get_updates\n",
      "    updates = super().get_updates(\n",
      "  File \"C:\\Users\\JABIR\\AppData\\Roaming\\Python\\Python38\\site-packages\\telegram\\bot.py\", line 130, in decorator\n",
      "    result = func(*args, **kwargs)\n",
      "  File \"C:\\Users\\JABIR\\AppData\\Roaming\\Python\\Python38\\site-packages\\telegram\\bot.py\", line 2861, in get_updates\n",
      "    self._post(\n",
      "  File \"C:\\Users\\JABIR\\AppData\\Roaming\\Python\\Python38\\site-packages\\telegram\\bot.py\", line 295, in _post\n",
      "    return self.request.post(\n",
      "  File \"C:\\Users\\JABIR\\AppData\\Roaming\\Python\\Python38\\site-packages\\telegram\\utils\\request.py\", line 356, in post\n",
      "    result = self._request_wrapper(\n",
      "  File \"C:\\Users\\JABIR\\AppData\\Roaming\\Python\\Python38\\site-packages\\telegram\\utils\\request.py\", line 283, in _request_wrapper\n",
      "    raise Conflict(message)\n",
      "telegram.error.Conflict: Conflict: terminated by other getUpdates request; make sure that only one bot instance is running\n",
      "Error while getting Updates: Conflict: terminated by other getUpdates request; make sure that only one bot instance is running\n",
      "No error handlers are registered, logging exception.\n",
      "Traceback (most recent call last):\n",
      "  File \"C:\\Users\\JABIR\\AppData\\Roaming\\Python\\Python38\\site-packages\\telegram\\ext\\updater.py\", line 646, in _network_loop_retry\n",
      "    if not action_cb():\n",
      "  File \"C:\\Users\\JABIR\\AppData\\Roaming\\Python\\Python38\\site-packages\\telegram\\ext\\updater.py\", line 597, in polling_action_cb\n",
      "    updates = self.bot.get_updates(\n",
      "  File \"C:\\Users\\JABIR\\AppData\\Roaming\\Python\\Python38\\site-packages\\telegram\\ext\\extbot.py\", line 222, in get_updates\n",
      "    updates = super().get_updates(\n",
      "  File \"C:\\Users\\JABIR\\AppData\\Roaming\\Python\\Python38\\site-packages\\telegram\\bot.py\", line 130, in decorator\n",
      "    result = func(*args, **kwargs)\n",
      "  File \"C:\\Users\\JABIR\\AppData\\Roaming\\Python\\Python38\\site-packages\\telegram\\bot.py\", line 2861, in get_updates\n",
      "    self._post(\n",
      "  File \"C:\\Users\\JABIR\\AppData\\Roaming\\Python\\Python38\\site-packages\\telegram\\bot.py\", line 295, in _post\n",
      "    return self.request.post(\n",
      "  File \"C:\\Users\\JABIR\\AppData\\Roaming\\Python\\Python38\\site-packages\\telegram\\utils\\request.py\", line 356, in post\n",
      "    result = self._request_wrapper(\n",
      "  File \"C:\\Users\\JABIR\\AppData\\Roaming\\Python\\Python38\\site-packages\\telegram\\utils\\request.py\", line 283, in _request_wrapper\n",
      "    raise Conflict(message)\n",
      "telegram.error.Conflict: Conflict: terminated by other getUpdates request; make sure that only one bot instance is running\n",
      "Error while getting Updates: Conflict: terminated by other getUpdates request; make sure that only one bot instance is running\n",
      "No error handlers are registered, logging exception.\n",
      "Traceback (most recent call last):\n",
      "  File \"C:\\Users\\JABIR\\AppData\\Roaming\\Python\\Python38\\site-packages\\telegram\\ext\\updater.py\", line 646, in _network_loop_retry\n",
      "    if not action_cb():\n",
      "  File \"C:\\Users\\JABIR\\AppData\\Roaming\\Python\\Python38\\site-packages\\telegram\\ext\\updater.py\", line 597, in polling_action_cb\n",
      "    updates = self.bot.get_updates(\n",
      "  File \"C:\\Users\\JABIR\\AppData\\Roaming\\Python\\Python38\\site-packages\\telegram\\ext\\extbot.py\", line 222, in get_updates\n",
      "    updates = super().get_updates(\n",
      "  File \"C:\\Users\\JABIR\\AppData\\Roaming\\Python\\Python38\\site-packages\\telegram\\bot.py\", line 130, in decorator\n",
      "    result = func(*args, **kwargs)\n",
      "  File \"C:\\Users\\JABIR\\AppData\\Roaming\\Python\\Python38\\site-packages\\telegram\\bot.py\", line 2861, in get_updates\n",
      "    self._post(\n",
      "  File \"C:\\Users\\JABIR\\AppData\\Roaming\\Python\\Python38\\site-packages\\telegram\\bot.py\", line 295, in _post\n",
      "    return self.request.post(\n",
      "  File \"C:\\Users\\JABIR\\AppData\\Roaming\\Python\\Python38\\site-packages\\telegram\\utils\\request.py\", line 356, in post\n",
      "    result = self._request_wrapper(\n",
      "  File \"C:\\Users\\JABIR\\AppData\\Roaming\\Python\\Python38\\site-packages\\telegram\\utils\\request.py\", line 283, in _request_wrapper\n",
      "    raise Conflict(message)\n",
      "telegram.error.Conflict: Conflict: terminated by other getUpdates request; make sure that only one bot instance is running\n",
      "Error while getting Updates: Conflict: terminated by other getUpdates request; make sure that only one bot instance is running\n",
      "No error handlers are registered, logging exception.\n",
      "Traceback (most recent call last):\n",
      "  File \"C:\\Users\\JABIR\\AppData\\Roaming\\Python\\Python38\\site-packages\\telegram\\ext\\updater.py\", line 646, in _network_loop_retry\n",
      "    if not action_cb():\n",
      "  File \"C:\\Users\\JABIR\\AppData\\Roaming\\Python\\Python38\\site-packages\\telegram\\ext\\updater.py\", line 597, in polling_action_cb\n",
      "    updates = self.bot.get_updates(\n",
      "  File \"C:\\Users\\JABIR\\AppData\\Roaming\\Python\\Python38\\site-packages\\telegram\\ext\\extbot.py\", line 222, in get_updates\n",
      "    updates = super().get_updates(\n",
      "  File \"C:\\Users\\JABIR\\AppData\\Roaming\\Python\\Python38\\site-packages\\telegram\\bot.py\", line 130, in decorator\n",
      "    result = func(*args, **kwargs)\n",
      "  File \"C:\\Users\\JABIR\\AppData\\Roaming\\Python\\Python38\\site-packages\\telegram\\bot.py\", line 2861, in get_updates\n",
      "    self._post(\n",
      "  File \"C:\\Users\\JABIR\\AppData\\Roaming\\Python\\Python38\\site-packages\\telegram\\bot.py\", line 295, in _post\n",
      "    return self.request.post(\n",
      "  File \"C:\\Users\\JABIR\\AppData\\Roaming\\Python\\Python38\\site-packages\\telegram\\utils\\request.py\", line 356, in post\n",
      "    result = self._request_wrapper(\n",
      "  File \"C:\\Users\\JABIR\\AppData\\Roaming\\Python\\Python38\\site-packages\\telegram\\utils\\request.py\", line 283, in _request_wrapper\n",
      "    raise Conflict(message)\n",
      "telegram.error.Conflict: Conflict: terminated by other getUpdates request; make sure that only one bot instance is running\n",
      "Error while getting Updates: Conflict: terminated by other getUpdates request; make sure that only one bot instance is running\n",
      "No error handlers are registered, logging exception.\n",
      "Traceback (most recent call last):\n",
      "  File \"C:\\Users\\JABIR\\AppData\\Roaming\\Python\\Python38\\site-packages\\telegram\\ext\\updater.py\", line 646, in _network_loop_retry\n",
      "    if not action_cb():\n",
      "  File \"C:\\Users\\JABIR\\AppData\\Roaming\\Python\\Python38\\site-packages\\telegram\\ext\\updater.py\", line 597, in polling_action_cb\n",
      "    updates = self.bot.get_updates(\n",
      "  File \"C:\\Users\\JABIR\\AppData\\Roaming\\Python\\Python38\\site-packages\\telegram\\ext\\extbot.py\", line 222, in get_updates\n",
      "    updates = super().get_updates(\n",
      "  File \"C:\\Users\\JABIR\\AppData\\Roaming\\Python\\Python38\\site-packages\\telegram\\bot.py\", line 130, in decorator\n",
      "    result = func(*args, **kwargs)\n",
      "  File \"C:\\Users\\JABIR\\AppData\\Roaming\\Python\\Python38\\site-packages\\telegram\\bot.py\", line 2861, in get_updates\n",
      "    self._post(\n",
      "  File \"C:\\Users\\JABIR\\AppData\\Roaming\\Python\\Python38\\site-packages\\telegram\\bot.py\", line 295, in _post\n",
      "    return self.request.post(\n",
      "  File \"C:\\Users\\JABIR\\AppData\\Roaming\\Python\\Python38\\site-packages\\telegram\\utils\\request.py\", line 356, in post\n",
      "    result = self._request_wrapper(\n",
      "  File \"C:\\Users\\JABIR\\AppData\\Roaming\\Python\\Python38\\site-packages\\telegram\\utils\\request.py\", line 283, in _request_wrapper\n",
      "    raise Conflict(message)\n",
      "telegram.error.Conflict: Conflict: terminated by other getUpdates request; make sure that only one bot instance is running\n"
     ]
    },
    {
     "name": "stderr",
     "output_type": "stream",
     "text": [
      "Error while getting Updates: Conflict: terminated by other getUpdates request; make sure that only one bot instance is running\n",
      "No error handlers are registered, logging exception.\n",
      "Traceback (most recent call last):\n",
      "  File \"C:\\Users\\JABIR\\AppData\\Roaming\\Python\\Python38\\site-packages\\telegram\\ext\\updater.py\", line 646, in _network_loop_retry\n",
      "    if not action_cb():\n",
      "  File \"C:\\Users\\JABIR\\AppData\\Roaming\\Python\\Python38\\site-packages\\telegram\\ext\\updater.py\", line 597, in polling_action_cb\n",
      "    updates = self.bot.get_updates(\n",
      "  File \"C:\\Users\\JABIR\\AppData\\Roaming\\Python\\Python38\\site-packages\\telegram\\ext\\extbot.py\", line 222, in get_updates\n",
      "    updates = super().get_updates(\n",
      "  File \"C:\\Users\\JABIR\\AppData\\Roaming\\Python\\Python38\\site-packages\\telegram\\bot.py\", line 130, in decorator\n",
      "    result = func(*args, **kwargs)\n",
      "  File \"C:\\Users\\JABIR\\AppData\\Roaming\\Python\\Python38\\site-packages\\telegram\\bot.py\", line 2861, in get_updates\n",
      "    self._post(\n",
      "  File \"C:\\Users\\JABIR\\AppData\\Roaming\\Python\\Python38\\site-packages\\telegram\\bot.py\", line 295, in _post\n",
      "    return self.request.post(\n",
      "  File \"C:\\Users\\JABIR\\AppData\\Roaming\\Python\\Python38\\site-packages\\telegram\\utils\\request.py\", line 356, in post\n",
      "    result = self._request_wrapper(\n",
      "  File \"C:\\Users\\JABIR\\AppData\\Roaming\\Python\\Python38\\site-packages\\telegram\\utils\\request.py\", line 283, in _request_wrapper\n",
      "    raise Conflict(message)\n",
      "telegram.error.Conflict: Conflict: terminated by other getUpdates request; make sure that only one bot instance is running\n",
      "Error while getting Updates: Conflict: terminated by other getUpdates request; make sure that only one bot instance is running\n",
      "No error handlers are registered, logging exception.\n",
      "Traceback (most recent call last):\n",
      "  File \"C:\\Users\\JABIR\\AppData\\Roaming\\Python\\Python38\\site-packages\\telegram\\ext\\updater.py\", line 646, in _network_loop_retry\n",
      "    if not action_cb():\n",
      "  File \"C:\\Users\\JABIR\\AppData\\Roaming\\Python\\Python38\\site-packages\\telegram\\ext\\updater.py\", line 597, in polling_action_cb\n",
      "    updates = self.bot.get_updates(\n",
      "  File \"C:\\Users\\JABIR\\AppData\\Roaming\\Python\\Python38\\site-packages\\telegram\\ext\\extbot.py\", line 222, in get_updates\n",
      "    updates = super().get_updates(\n",
      "  File \"C:\\Users\\JABIR\\AppData\\Roaming\\Python\\Python38\\site-packages\\telegram\\bot.py\", line 130, in decorator\n",
      "    result = func(*args, **kwargs)\n",
      "  File \"C:\\Users\\JABIR\\AppData\\Roaming\\Python\\Python38\\site-packages\\telegram\\bot.py\", line 2861, in get_updates\n",
      "    self._post(\n",
      "  File \"C:\\Users\\JABIR\\AppData\\Roaming\\Python\\Python38\\site-packages\\telegram\\bot.py\", line 295, in _post\n",
      "    return self.request.post(\n",
      "  File \"C:\\Users\\JABIR\\AppData\\Roaming\\Python\\Python38\\site-packages\\telegram\\utils\\request.py\", line 356, in post\n",
      "    result = self._request_wrapper(\n",
      "  File \"C:\\Users\\JABIR\\AppData\\Roaming\\Python\\Python38\\site-packages\\telegram\\utils\\request.py\", line 283, in _request_wrapper\n",
      "    raise Conflict(message)\n",
      "telegram.error.Conflict: Conflict: terminated by other getUpdates request; make sure that only one bot instance is running\n",
      "Error while getting Updates: Conflict: terminated by other getUpdates request; make sure that only one bot instance is running\n",
      "No error handlers are registered, logging exception.\n",
      "Traceback (most recent call last):\n",
      "  File \"C:\\Users\\JABIR\\AppData\\Roaming\\Python\\Python38\\site-packages\\telegram\\ext\\updater.py\", line 646, in _network_loop_retry\n",
      "    if not action_cb():\n",
      "  File \"C:\\Users\\JABIR\\AppData\\Roaming\\Python\\Python38\\site-packages\\telegram\\ext\\updater.py\", line 597, in polling_action_cb\n",
      "    updates = self.bot.get_updates(\n",
      "  File \"C:\\Users\\JABIR\\AppData\\Roaming\\Python\\Python38\\site-packages\\telegram\\ext\\extbot.py\", line 222, in get_updates\n",
      "    updates = super().get_updates(\n",
      "  File \"C:\\Users\\JABIR\\AppData\\Roaming\\Python\\Python38\\site-packages\\telegram\\bot.py\", line 130, in decorator\n",
      "    result = func(*args, **kwargs)\n",
      "  File \"C:\\Users\\JABIR\\AppData\\Roaming\\Python\\Python38\\site-packages\\telegram\\bot.py\", line 2861, in get_updates\n",
      "    self._post(\n",
      "  File \"C:\\Users\\JABIR\\AppData\\Roaming\\Python\\Python38\\site-packages\\telegram\\bot.py\", line 295, in _post\n",
      "    return self.request.post(\n",
      "  File \"C:\\Users\\JABIR\\AppData\\Roaming\\Python\\Python38\\site-packages\\telegram\\utils\\request.py\", line 356, in post\n",
      "    result = self._request_wrapper(\n",
      "  File \"C:\\Users\\JABIR\\AppData\\Roaming\\Python\\Python38\\site-packages\\telegram\\utils\\request.py\", line 283, in _request_wrapper\n",
      "    raise Conflict(message)\n",
      "telegram.error.Conflict: Conflict: terminated by other getUpdates request; make sure that only one bot instance is running\n",
      "Error while getting Updates: Conflict: terminated by other getUpdates request; make sure that only one bot instance is running\n",
      "No error handlers are registered, logging exception.\n",
      "Traceback (most recent call last):\n",
      "  File \"C:\\Users\\JABIR\\AppData\\Roaming\\Python\\Python38\\site-packages\\telegram\\ext\\updater.py\", line 646, in _network_loop_retry\n",
      "    if not action_cb():\n",
      "  File \"C:\\Users\\JABIR\\AppData\\Roaming\\Python\\Python38\\site-packages\\telegram\\ext\\updater.py\", line 597, in polling_action_cb\n",
      "    updates = self.bot.get_updates(\n",
      "  File \"C:\\Users\\JABIR\\AppData\\Roaming\\Python\\Python38\\site-packages\\telegram\\ext\\extbot.py\", line 222, in get_updates\n",
      "    updates = super().get_updates(\n",
      "  File \"C:\\Users\\JABIR\\AppData\\Roaming\\Python\\Python38\\site-packages\\telegram\\bot.py\", line 130, in decorator\n",
      "    result = func(*args, **kwargs)\n",
      "  File \"C:\\Users\\JABIR\\AppData\\Roaming\\Python\\Python38\\site-packages\\telegram\\bot.py\", line 2861, in get_updates\n",
      "    self._post(\n",
      "  File \"C:\\Users\\JABIR\\AppData\\Roaming\\Python\\Python38\\site-packages\\telegram\\bot.py\", line 295, in _post\n",
      "    return self.request.post(\n",
      "  File \"C:\\Users\\JABIR\\AppData\\Roaming\\Python\\Python38\\site-packages\\telegram\\utils\\request.py\", line 356, in post\n",
      "    result = self._request_wrapper(\n",
      "  File \"C:\\Users\\JABIR\\AppData\\Roaming\\Python\\Python38\\site-packages\\telegram\\utils\\request.py\", line 283, in _request_wrapper\n",
      "    raise Conflict(message)\n",
      "telegram.error.Conflict: Conflict: terminated by other getUpdates request; make sure that only one bot instance is running\n",
      "Error while getting Updates: Conflict: terminated by other getUpdates request; make sure that only one bot instance is running\n",
      "No error handlers are registered, logging exception.\n",
      "Traceback (most recent call last):\n",
      "  File \"C:\\Users\\JABIR\\AppData\\Roaming\\Python\\Python38\\site-packages\\telegram\\ext\\updater.py\", line 646, in _network_loop_retry\n",
      "    if not action_cb():\n",
      "  File \"C:\\Users\\JABIR\\AppData\\Roaming\\Python\\Python38\\site-packages\\telegram\\ext\\updater.py\", line 597, in polling_action_cb\n",
      "    updates = self.bot.get_updates(\n",
      "  File \"C:\\Users\\JABIR\\AppData\\Roaming\\Python\\Python38\\site-packages\\telegram\\ext\\extbot.py\", line 222, in get_updates\n",
      "    updates = super().get_updates(\n",
      "  File \"C:\\Users\\JABIR\\AppData\\Roaming\\Python\\Python38\\site-packages\\telegram\\bot.py\", line 130, in decorator\n",
      "    result = func(*args, **kwargs)\n",
      "  File \"C:\\Users\\JABIR\\AppData\\Roaming\\Python\\Python38\\site-packages\\telegram\\bot.py\", line 2861, in get_updates\n",
      "    self._post(\n",
      "  File \"C:\\Users\\JABIR\\AppData\\Roaming\\Python\\Python38\\site-packages\\telegram\\bot.py\", line 295, in _post\n",
      "    return self.request.post(\n",
      "  File \"C:\\Users\\JABIR\\AppData\\Roaming\\Python\\Python38\\site-packages\\telegram\\utils\\request.py\", line 356, in post\n",
      "    result = self._request_wrapper(\n",
      "  File \"C:\\Users\\JABIR\\AppData\\Roaming\\Python\\Python38\\site-packages\\telegram\\utils\\request.py\", line 283, in _request_wrapper\n",
      "    raise Conflict(message)\n",
      "telegram.error.Conflict: Conflict: terminated by other getUpdates request; make sure that only one bot instance is running\n",
      "Error while getting Updates: Conflict: terminated by other getUpdates request; make sure that only one bot instance is running\n",
      "No error handlers are registered, logging exception.\n",
      "Traceback (most recent call last):\n",
      "  File \"C:\\Users\\JABIR\\AppData\\Roaming\\Python\\Python38\\site-packages\\telegram\\ext\\updater.py\", line 646, in _network_loop_retry\n",
      "    if not action_cb():\n",
      "  File \"C:\\Users\\JABIR\\AppData\\Roaming\\Python\\Python38\\site-packages\\telegram\\ext\\updater.py\", line 597, in polling_action_cb\n",
      "    updates = self.bot.get_updates(\n",
      "  File \"C:\\Users\\JABIR\\AppData\\Roaming\\Python\\Python38\\site-packages\\telegram\\ext\\extbot.py\", line 222, in get_updates\n",
      "    updates = super().get_updates(\n",
      "  File \"C:\\Users\\JABIR\\AppData\\Roaming\\Python\\Python38\\site-packages\\telegram\\bot.py\", line 130, in decorator\n",
      "    result = func(*args, **kwargs)\n",
      "  File \"C:\\Users\\JABIR\\AppData\\Roaming\\Python\\Python38\\site-packages\\telegram\\bot.py\", line 2861, in get_updates\n",
      "    self._post(\n",
      "  File \"C:\\Users\\JABIR\\AppData\\Roaming\\Python\\Python38\\site-packages\\telegram\\bot.py\", line 295, in _post\n",
      "    return self.request.post(\n",
      "  File \"C:\\Users\\JABIR\\AppData\\Roaming\\Python\\Python38\\site-packages\\telegram\\utils\\request.py\", line 356, in post\n",
      "    result = self._request_wrapper(\n",
      "  File \"C:\\Users\\JABIR\\AppData\\Roaming\\Python\\Python38\\site-packages\\telegram\\utils\\request.py\", line 283, in _request_wrapper\n",
      "    raise Conflict(message)\n",
      "telegram.error.Conflict: Conflict: terminated by other getUpdates request; make sure that only one bot instance is running\n"
     ]
    },
    {
     "name": "stderr",
     "output_type": "stream",
     "text": [
      "Error while getting Updates: Conflict: terminated by other getUpdates request; make sure that only one bot instance is running\n",
      "No error handlers are registered, logging exception.\n",
      "Traceback (most recent call last):\n",
      "  File \"C:\\Users\\JABIR\\AppData\\Roaming\\Python\\Python38\\site-packages\\telegram\\ext\\updater.py\", line 646, in _network_loop_retry\n",
      "    if not action_cb():\n",
      "  File \"C:\\Users\\JABIR\\AppData\\Roaming\\Python\\Python38\\site-packages\\telegram\\ext\\updater.py\", line 597, in polling_action_cb\n",
      "    updates = self.bot.get_updates(\n",
      "  File \"C:\\Users\\JABIR\\AppData\\Roaming\\Python\\Python38\\site-packages\\telegram\\ext\\extbot.py\", line 222, in get_updates\n",
      "    updates = super().get_updates(\n",
      "  File \"C:\\Users\\JABIR\\AppData\\Roaming\\Python\\Python38\\site-packages\\telegram\\bot.py\", line 130, in decorator\n",
      "    result = func(*args, **kwargs)\n",
      "  File \"C:\\Users\\JABIR\\AppData\\Roaming\\Python\\Python38\\site-packages\\telegram\\bot.py\", line 2861, in get_updates\n",
      "    self._post(\n",
      "  File \"C:\\Users\\JABIR\\AppData\\Roaming\\Python\\Python38\\site-packages\\telegram\\bot.py\", line 295, in _post\n",
      "    return self.request.post(\n",
      "  File \"C:\\Users\\JABIR\\AppData\\Roaming\\Python\\Python38\\site-packages\\telegram\\utils\\request.py\", line 356, in post\n",
      "    result = self._request_wrapper(\n",
      "  File \"C:\\Users\\JABIR\\AppData\\Roaming\\Python\\Python38\\site-packages\\telegram\\utils\\request.py\", line 283, in _request_wrapper\n",
      "    raise Conflict(message)\n",
      "telegram.error.Conflict: Conflict: terminated by other getUpdates request; make sure that only one bot instance is running\n",
      "Error while getting Updates: Conflict: terminated by other getUpdates request; make sure that only one bot instance is running\n",
      "No error handlers are registered, logging exception.\n",
      "Traceback (most recent call last):\n",
      "  File \"C:\\Users\\JABIR\\AppData\\Roaming\\Python\\Python38\\site-packages\\telegram\\ext\\updater.py\", line 646, in _network_loop_retry\n",
      "    if not action_cb():\n",
      "  File \"C:\\Users\\JABIR\\AppData\\Roaming\\Python\\Python38\\site-packages\\telegram\\ext\\updater.py\", line 597, in polling_action_cb\n",
      "    updates = self.bot.get_updates(\n",
      "  File \"C:\\Users\\JABIR\\AppData\\Roaming\\Python\\Python38\\site-packages\\telegram\\ext\\extbot.py\", line 222, in get_updates\n",
      "    updates = super().get_updates(\n",
      "  File \"C:\\Users\\JABIR\\AppData\\Roaming\\Python\\Python38\\site-packages\\telegram\\bot.py\", line 130, in decorator\n",
      "    result = func(*args, **kwargs)\n",
      "  File \"C:\\Users\\JABIR\\AppData\\Roaming\\Python\\Python38\\site-packages\\telegram\\bot.py\", line 2861, in get_updates\n",
      "    self._post(\n",
      "  File \"C:\\Users\\JABIR\\AppData\\Roaming\\Python\\Python38\\site-packages\\telegram\\bot.py\", line 295, in _post\n",
      "    return self.request.post(\n",
      "  File \"C:\\Users\\JABIR\\AppData\\Roaming\\Python\\Python38\\site-packages\\telegram\\utils\\request.py\", line 356, in post\n",
      "    result = self._request_wrapper(\n",
      "  File \"C:\\Users\\JABIR\\AppData\\Roaming\\Python\\Python38\\site-packages\\telegram\\utils\\request.py\", line 283, in _request_wrapper\n",
      "    raise Conflict(message)\n",
      "telegram.error.Conflict: Conflict: terminated by other getUpdates request; make sure that only one bot instance is running\n",
      "Error while getting Updates: Conflict: terminated by other getUpdates request; make sure that only one bot instance is running\n",
      "No error handlers are registered, logging exception.\n",
      "Traceback (most recent call last):\n",
      "  File \"C:\\Users\\JABIR\\AppData\\Roaming\\Python\\Python38\\site-packages\\telegram\\ext\\updater.py\", line 646, in _network_loop_retry\n",
      "    if not action_cb():\n",
      "  File \"C:\\Users\\JABIR\\AppData\\Roaming\\Python\\Python38\\site-packages\\telegram\\ext\\updater.py\", line 597, in polling_action_cb\n",
      "    updates = self.bot.get_updates(\n",
      "  File \"C:\\Users\\JABIR\\AppData\\Roaming\\Python\\Python38\\site-packages\\telegram\\ext\\extbot.py\", line 222, in get_updates\n",
      "    updates = super().get_updates(\n",
      "  File \"C:\\Users\\JABIR\\AppData\\Roaming\\Python\\Python38\\site-packages\\telegram\\bot.py\", line 130, in decorator\n",
      "    result = func(*args, **kwargs)\n",
      "  File \"C:\\Users\\JABIR\\AppData\\Roaming\\Python\\Python38\\site-packages\\telegram\\bot.py\", line 2861, in get_updates\n",
      "    self._post(\n",
      "  File \"C:\\Users\\JABIR\\AppData\\Roaming\\Python\\Python38\\site-packages\\telegram\\bot.py\", line 295, in _post\n",
      "    return self.request.post(\n",
      "  File \"C:\\Users\\JABIR\\AppData\\Roaming\\Python\\Python38\\site-packages\\telegram\\utils\\request.py\", line 356, in post\n",
      "    result = self._request_wrapper(\n",
      "  File \"C:\\Users\\JABIR\\AppData\\Roaming\\Python\\Python38\\site-packages\\telegram\\utils\\request.py\", line 283, in _request_wrapper\n",
      "    raise Conflict(message)\n",
      "telegram.error.Conflict: Conflict: terminated by other getUpdates request; make sure that only one bot instance is running\n",
      "Error while getting Updates: Conflict: terminated by other getUpdates request; make sure that only one bot instance is running\n",
      "No error handlers are registered, logging exception.\n",
      "Traceback (most recent call last):\n",
      "  File \"C:\\Users\\JABIR\\AppData\\Roaming\\Python\\Python38\\site-packages\\telegram\\ext\\updater.py\", line 646, in _network_loop_retry\n",
      "    if not action_cb():\n",
      "  File \"C:\\Users\\JABIR\\AppData\\Roaming\\Python\\Python38\\site-packages\\telegram\\ext\\updater.py\", line 597, in polling_action_cb\n",
      "    updates = self.bot.get_updates(\n",
      "  File \"C:\\Users\\JABIR\\AppData\\Roaming\\Python\\Python38\\site-packages\\telegram\\ext\\extbot.py\", line 222, in get_updates\n",
      "    updates = super().get_updates(\n",
      "  File \"C:\\Users\\JABIR\\AppData\\Roaming\\Python\\Python38\\site-packages\\telegram\\bot.py\", line 130, in decorator\n",
      "    result = func(*args, **kwargs)\n",
      "  File \"C:\\Users\\JABIR\\AppData\\Roaming\\Python\\Python38\\site-packages\\telegram\\bot.py\", line 2861, in get_updates\n",
      "    self._post(\n",
      "  File \"C:\\Users\\JABIR\\AppData\\Roaming\\Python\\Python38\\site-packages\\telegram\\bot.py\", line 295, in _post\n",
      "    return self.request.post(\n",
      "  File \"C:\\Users\\JABIR\\AppData\\Roaming\\Python\\Python38\\site-packages\\telegram\\utils\\request.py\", line 356, in post\n",
      "    result = self._request_wrapper(\n",
      "  File \"C:\\Users\\JABIR\\AppData\\Roaming\\Python\\Python38\\site-packages\\telegram\\utils\\request.py\", line 283, in _request_wrapper\n",
      "    raise Conflict(message)\n",
      "telegram.error.Conflict: Conflict: terminated by other getUpdates request; make sure that only one bot instance is running\n",
      "Error while getting Updates: Conflict: terminated by other getUpdates request; make sure that only one bot instance is running\n",
      "No error handlers are registered, logging exception.\n",
      "Traceback (most recent call last):\n",
      "  File \"C:\\Users\\JABIR\\AppData\\Roaming\\Python\\Python38\\site-packages\\telegram\\ext\\updater.py\", line 646, in _network_loop_retry\n",
      "    if not action_cb():\n",
      "  File \"C:\\Users\\JABIR\\AppData\\Roaming\\Python\\Python38\\site-packages\\telegram\\ext\\updater.py\", line 597, in polling_action_cb\n",
      "    updates = self.bot.get_updates(\n",
      "  File \"C:\\Users\\JABIR\\AppData\\Roaming\\Python\\Python38\\site-packages\\telegram\\ext\\extbot.py\", line 222, in get_updates\n",
      "    updates = super().get_updates(\n",
      "  File \"C:\\Users\\JABIR\\AppData\\Roaming\\Python\\Python38\\site-packages\\telegram\\bot.py\", line 130, in decorator\n",
      "    result = func(*args, **kwargs)\n",
      "  File \"C:\\Users\\JABIR\\AppData\\Roaming\\Python\\Python38\\site-packages\\telegram\\bot.py\", line 2861, in get_updates\n",
      "    self._post(\n",
      "  File \"C:\\Users\\JABIR\\AppData\\Roaming\\Python\\Python38\\site-packages\\telegram\\bot.py\", line 295, in _post\n",
      "    return self.request.post(\n",
      "  File \"C:\\Users\\JABIR\\AppData\\Roaming\\Python\\Python38\\site-packages\\telegram\\utils\\request.py\", line 356, in post\n",
      "    result = self._request_wrapper(\n",
      "  File \"C:\\Users\\JABIR\\AppData\\Roaming\\Python\\Python38\\site-packages\\telegram\\utils\\request.py\", line 283, in _request_wrapper\n",
      "    raise Conflict(message)\n",
      "telegram.error.Conflict: Conflict: terminated by other getUpdates request; make sure that only one bot instance is running\n",
      "Error while getting Updates: Conflict: terminated by other getUpdates request; make sure that only one bot instance is running\n",
      "No error handlers are registered, logging exception.\n",
      "Traceback (most recent call last):\n",
      "  File \"C:\\Users\\JABIR\\AppData\\Roaming\\Python\\Python38\\site-packages\\telegram\\ext\\updater.py\", line 646, in _network_loop_retry\n",
      "    if not action_cb():\n",
      "  File \"C:\\Users\\JABIR\\AppData\\Roaming\\Python\\Python38\\site-packages\\telegram\\ext\\updater.py\", line 597, in polling_action_cb\n",
      "    updates = self.bot.get_updates(\n",
      "  File \"C:\\Users\\JABIR\\AppData\\Roaming\\Python\\Python38\\site-packages\\telegram\\ext\\extbot.py\", line 222, in get_updates\n",
      "    updates = super().get_updates(\n",
      "  File \"C:\\Users\\JABIR\\AppData\\Roaming\\Python\\Python38\\site-packages\\telegram\\bot.py\", line 130, in decorator\n",
      "    result = func(*args, **kwargs)\n",
      "  File \"C:\\Users\\JABIR\\AppData\\Roaming\\Python\\Python38\\site-packages\\telegram\\bot.py\", line 2861, in get_updates\n",
      "    self._post(\n",
      "  File \"C:\\Users\\JABIR\\AppData\\Roaming\\Python\\Python38\\site-packages\\telegram\\bot.py\", line 295, in _post\n",
      "    return self.request.post(\n",
      "  File \"C:\\Users\\JABIR\\AppData\\Roaming\\Python\\Python38\\site-packages\\telegram\\utils\\request.py\", line 356, in post\n",
      "    result = self._request_wrapper(\n",
      "  File \"C:\\Users\\JABIR\\AppData\\Roaming\\Python\\Python38\\site-packages\\telegram\\utils\\request.py\", line 283, in _request_wrapper\n",
      "    raise Conflict(message)\n",
      "telegram.error.Conflict: Conflict: terminated by other getUpdates request; make sure that only one bot instance is running\n"
     ]
    },
    {
     "name": "stderr",
     "output_type": "stream",
     "text": [
      "Error while getting Updates: Conflict: terminated by other getUpdates request; make sure that only one bot instance is running\n",
      "No error handlers are registered, logging exception.\n",
      "Traceback (most recent call last):\n",
      "  File \"C:\\Users\\JABIR\\AppData\\Roaming\\Python\\Python38\\site-packages\\telegram\\ext\\updater.py\", line 646, in _network_loop_retry\n",
      "    if not action_cb():\n",
      "  File \"C:\\Users\\JABIR\\AppData\\Roaming\\Python\\Python38\\site-packages\\telegram\\ext\\updater.py\", line 597, in polling_action_cb\n",
      "    updates = self.bot.get_updates(\n",
      "  File \"C:\\Users\\JABIR\\AppData\\Roaming\\Python\\Python38\\site-packages\\telegram\\ext\\extbot.py\", line 222, in get_updates\n",
      "    updates = super().get_updates(\n",
      "  File \"C:\\Users\\JABIR\\AppData\\Roaming\\Python\\Python38\\site-packages\\telegram\\bot.py\", line 130, in decorator\n",
      "    result = func(*args, **kwargs)\n",
      "  File \"C:\\Users\\JABIR\\AppData\\Roaming\\Python\\Python38\\site-packages\\telegram\\bot.py\", line 2861, in get_updates\n",
      "    self._post(\n",
      "  File \"C:\\Users\\JABIR\\AppData\\Roaming\\Python\\Python38\\site-packages\\telegram\\bot.py\", line 295, in _post\n",
      "    return self.request.post(\n",
      "  File \"C:\\Users\\JABIR\\AppData\\Roaming\\Python\\Python38\\site-packages\\telegram\\utils\\request.py\", line 356, in post\n",
      "    result = self._request_wrapper(\n",
      "  File \"C:\\Users\\JABIR\\AppData\\Roaming\\Python\\Python38\\site-packages\\telegram\\utils\\request.py\", line 283, in _request_wrapper\n",
      "    raise Conflict(message)\n",
      "telegram.error.Conflict: Conflict: terminated by other getUpdates request; make sure that only one bot instance is running\n",
      "Error while getting Updates: Conflict: terminated by other getUpdates request; make sure that only one bot instance is running\n",
      "No error handlers are registered, logging exception.\n",
      "Traceback (most recent call last):\n",
      "  File \"C:\\Users\\JABIR\\AppData\\Roaming\\Python\\Python38\\site-packages\\telegram\\ext\\updater.py\", line 646, in _network_loop_retry\n",
      "    if not action_cb():\n",
      "  File \"C:\\Users\\JABIR\\AppData\\Roaming\\Python\\Python38\\site-packages\\telegram\\ext\\updater.py\", line 597, in polling_action_cb\n",
      "    updates = self.bot.get_updates(\n",
      "  File \"C:\\Users\\JABIR\\AppData\\Roaming\\Python\\Python38\\site-packages\\telegram\\ext\\extbot.py\", line 222, in get_updates\n",
      "    updates = super().get_updates(\n",
      "  File \"C:\\Users\\JABIR\\AppData\\Roaming\\Python\\Python38\\site-packages\\telegram\\bot.py\", line 130, in decorator\n",
      "    result = func(*args, **kwargs)\n",
      "  File \"C:\\Users\\JABIR\\AppData\\Roaming\\Python\\Python38\\site-packages\\telegram\\bot.py\", line 2861, in get_updates\n",
      "    self._post(\n",
      "  File \"C:\\Users\\JABIR\\AppData\\Roaming\\Python\\Python38\\site-packages\\telegram\\bot.py\", line 295, in _post\n",
      "    return self.request.post(\n",
      "  File \"C:\\Users\\JABIR\\AppData\\Roaming\\Python\\Python38\\site-packages\\telegram\\utils\\request.py\", line 356, in post\n",
      "    result = self._request_wrapper(\n",
      "  File \"C:\\Users\\JABIR\\AppData\\Roaming\\Python\\Python38\\site-packages\\telegram\\utils\\request.py\", line 283, in _request_wrapper\n",
      "    raise Conflict(message)\n",
      "telegram.error.Conflict: Conflict: terminated by other getUpdates request; make sure that only one bot instance is running\n",
      "Error while getting Updates: Conflict: terminated by other getUpdates request; make sure that only one bot instance is running\n",
      "No error handlers are registered, logging exception.\n",
      "Traceback (most recent call last):\n",
      "  File \"C:\\Users\\JABIR\\AppData\\Roaming\\Python\\Python38\\site-packages\\telegram\\ext\\updater.py\", line 646, in _network_loop_retry\n",
      "    if not action_cb():\n",
      "  File \"C:\\Users\\JABIR\\AppData\\Roaming\\Python\\Python38\\site-packages\\telegram\\ext\\updater.py\", line 597, in polling_action_cb\n",
      "    updates = self.bot.get_updates(\n",
      "  File \"C:\\Users\\JABIR\\AppData\\Roaming\\Python\\Python38\\site-packages\\telegram\\ext\\extbot.py\", line 222, in get_updates\n",
      "    updates = super().get_updates(\n",
      "  File \"C:\\Users\\JABIR\\AppData\\Roaming\\Python\\Python38\\site-packages\\telegram\\bot.py\", line 130, in decorator\n",
      "    result = func(*args, **kwargs)\n",
      "  File \"C:\\Users\\JABIR\\AppData\\Roaming\\Python\\Python38\\site-packages\\telegram\\bot.py\", line 2861, in get_updates\n",
      "    self._post(\n",
      "  File \"C:\\Users\\JABIR\\AppData\\Roaming\\Python\\Python38\\site-packages\\telegram\\bot.py\", line 295, in _post\n",
      "    return self.request.post(\n",
      "  File \"C:\\Users\\JABIR\\AppData\\Roaming\\Python\\Python38\\site-packages\\telegram\\utils\\request.py\", line 356, in post\n",
      "    result = self._request_wrapper(\n",
      "  File \"C:\\Users\\JABIR\\AppData\\Roaming\\Python\\Python38\\site-packages\\telegram\\utils\\request.py\", line 283, in _request_wrapper\n",
      "    raise Conflict(message)\n",
      "telegram.error.Conflict: Conflict: terminated by other getUpdates request; make sure that only one bot instance is running\n",
      "Error while getting Updates: Conflict: terminated by other getUpdates request; make sure that only one bot instance is running\n",
      "No error handlers are registered, logging exception.\n",
      "Traceback (most recent call last):\n",
      "  File \"C:\\Users\\JABIR\\AppData\\Roaming\\Python\\Python38\\site-packages\\telegram\\ext\\updater.py\", line 646, in _network_loop_retry\n",
      "    if not action_cb():\n",
      "  File \"C:\\Users\\JABIR\\AppData\\Roaming\\Python\\Python38\\site-packages\\telegram\\ext\\updater.py\", line 597, in polling_action_cb\n",
      "    updates = self.bot.get_updates(\n",
      "  File \"C:\\Users\\JABIR\\AppData\\Roaming\\Python\\Python38\\site-packages\\telegram\\ext\\extbot.py\", line 222, in get_updates\n",
      "    updates = super().get_updates(\n",
      "  File \"C:\\Users\\JABIR\\AppData\\Roaming\\Python\\Python38\\site-packages\\telegram\\bot.py\", line 130, in decorator\n",
      "    result = func(*args, **kwargs)\n",
      "  File \"C:\\Users\\JABIR\\AppData\\Roaming\\Python\\Python38\\site-packages\\telegram\\bot.py\", line 2861, in get_updates\n",
      "    self._post(\n",
      "  File \"C:\\Users\\JABIR\\AppData\\Roaming\\Python\\Python38\\site-packages\\telegram\\bot.py\", line 295, in _post\n",
      "    return self.request.post(\n",
      "  File \"C:\\Users\\JABIR\\AppData\\Roaming\\Python\\Python38\\site-packages\\telegram\\utils\\request.py\", line 356, in post\n",
      "    result = self._request_wrapper(\n",
      "  File \"C:\\Users\\JABIR\\AppData\\Roaming\\Python\\Python38\\site-packages\\telegram\\utils\\request.py\", line 283, in _request_wrapper\n",
      "    raise Conflict(message)\n",
      "telegram.error.Conflict: Conflict: terminated by other getUpdates request; make sure that only one bot instance is running\n",
      "Error while getting Updates: Conflict: terminated by other getUpdates request; make sure that only one bot instance is running\n",
      "No error handlers are registered, logging exception.\n",
      "Traceback (most recent call last):\n",
      "  File \"C:\\Users\\JABIR\\AppData\\Roaming\\Python\\Python38\\site-packages\\telegram\\ext\\updater.py\", line 646, in _network_loop_retry\n",
      "    if not action_cb():\n",
      "  File \"C:\\Users\\JABIR\\AppData\\Roaming\\Python\\Python38\\site-packages\\telegram\\ext\\updater.py\", line 597, in polling_action_cb\n",
      "    updates = self.bot.get_updates(\n",
      "  File \"C:\\Users\\JABIR\\AppData\\Roaming\\Python\\Python38\\site-packages\\telegram\\ext\\extbot.py\", line 222, in get_updates\n",
      "    updates = super().get_updates(\n",
      "  File \"C:\\Users\\JABIR\\AppData\\Roaming\\Python\\Python38\\site-packages\\telegram\\bot.py\", line 130, in decorator\n",
      "    result = func(*args, **kwargs)\n",
      "  File \"C:\\Users\\JABIR\\AppData\\Roaming\\Python\\Python38\\site-packages\\telegram\\bot.py\", line 2861, in get_updates\n",
      "    self._post(\n",
      "  File \"C:\\Users\\JABIR\\AppData\\Roaming\\Python\\Python38\\site-packages\\telegram\\bot.py\", line 295, in _post\n",
      "    return self.request.post(\n",
      "  File \"C:\\Users\\JABIR\\AppData\\Roaming\\Python\\Python38\\site-packages\\telegram\\utils\\request.py\", line 356, in post\n",
      "    result = self._request_wrapper(\n",
      "  File \"C:\\Users\\JABIR\\AppData\\Roaming\\Python\\Python38\\site-packages\\telegram\\utils\\request.py\", line 283, in _request_wrapper\n",
      "    raise Conflict(message)\n",
      "telegram.error.Conflict: Conflict: terminated by other getUpdates request; make sure that only one bot instance is running\n",
      "Error while getting Updates: Conflict: terminated by other getUpdates request; make sure that only one bot instance is running\n",
      "No error handlers are registered, logging exception.\n",
      "Traceback (most recent call last):\n",
      "  File \"C:\\Users\\JABIR\\AppData\\Roaming\\Python\\Python38\\site-packages\\telegram\\ext\\updater.py\", line 646, in _network_loop_retry\n",
      "    if not action_cb():\n",
      "  File \"C:\\Users\\JABIR\\AppData\\Roaming\\Python\\Python38\\site-packages\\telegram\\ext\\updater.py\", line 597, in polling_action_cb\n",
      "    updates = self.bot.get_updates(\n",
      "  File \"C:\\Users\\JABIR\\AppData\\Roaming\\Python\\Python38\\site-packages\\telegram\\ext\\extbot.py\", line 222, in get_updates\n",
      "    updates = super().get_updates(\n",
      "  File \"C:\\Users\\JABIR\\AppData\\Roaming\\Python\\Python38\\site-packages\\telegram\\bot.py\", line 130, in decorator\n",
      "    result = func(*args, **kwargs)\n",
      "  File \"C:\\Users\\JABIR\\AppData\\Roaming\\Python\\Python38\\site-packages\\telegram\\bot.py\", line 2861, in get_updates\n",
      "    self._post(\n",
      "  File \"C:\\Users\\JABIR\\AppData\\Roaming\\Python\\Python38\\site-packages\\telegram\\bot.py\", line 295, in _post\n",
      "    return self.request.post(\n",
      "  File \"C:\\Users\\JABIR\\AppData\\Roaming\\Python\\Python38\\site-packages\\telegram\\utils\\request.py\", line 356, in post\n",
      "    result = self._request_wrapper(\n",
      "  File \"C:\\Users\\JABIR\\AppData\\Roaming\\Python\\Python38\\site-packages\\telegram\\utils\\request.py\", line 283, in _request_wrapper\n",
      "    raise Conflict(message)\n",
      "telegram.error.Conflict: Conflict: terminated by other getUpdates request; make sure that only one bot instance is running\n"
     ]
    },
    {
     "name": "stderr",
     "output_type": "stream",
     "text": [
      "Error while getting Updates: Conflict: terminated by other getUpdates request; make sure that only one bot instance is running\n",
      "No error handlers are registered, logging exception.\n",
      "Traceback (most recent call last):\n",
      "  File \"C:\\Users\\JABIR\\AppData\\Roaming\\Python\\Python38\\site-packages\\telegram\\ext\\updater.py\", line 646, in _network_loop_retry\n",
      "    if not action_cb():\n",
      "  File \"C:\\Users\\JABIR\\AppData\\Roaming\\Python\\Python38\\site-packages\\telegram\\ext\\updater.py\", line 597, in polling_action_cb\n",
      "    updates = self.bot.get_updates(\n",
      "  File \"C:\\Users\\JABIR\\AppData\\Roaming\\Python\\Python38\\site-packages\\telegram\\ext\\extbot.py\", line 222, in get_updates\n",
      "    updates = super().get_updates(\n",
      "  File \"C:\\Users\\JABIR\\AppData\\Roaming\\Python\\Python38\\site-packages\\telegram\\bot.py\", line 130, in decorator\n",
      "    result = func(*args, **kwargs)\n",
      "  File \"C:\\Users\\JABIR\\AppData\\Roaming\\Python\\Python38\\site-packages\\telegram\\bot.py\", line 2861, in get_updates\n",
      "    self._post(\n",
      "  File \"C:\\Users\\JABIR\\AppData\\Roaming\\Python\\Python38\\site-packages\\telegram\\bot.py\", line 295, in _post\n",
      "    return self.request.post(\n",
      "  File \"C:\\Users\\JABIR\\AppData\\Roaming\\Python\\Python38\\site-packages\\telegram\\utils\\request.py\", line 356, in post\n",
      "    result = self._request_wrapper(\n",
      "  File \"C:\\Users\\JABIR\\AppData\\Roaming\\Python\\Python38\\site-packages\\telegram\\utils\\request.py\", line 283, in _request_wrapper\n",
      "    raise Conflict(message)\n",
      "telegram.error.Conflict: Conflict: terminated by other getUpdates request; make sure that only one bot instance is running\n",
      "Error while getting Updates: Conflict: terminated by other getUpdates request; make sure that only one bot instance is running\n",
      "No error handlers are registered, logging exception.\n",
      "Traceback (most recent call last):\n",
      "  File \"C:\\Users\\JABIR\\AppData\\Roaming\\Python\\Python38\\site-packages\\telegram\\ext\\updater.py\", line 646, in _network_loop_retry\n",
      "    if not action_cb():\n",
      "  File \"C:\\Users\\JABIR\\AppData\\Roaming\\Python\\Python38\\site-packages\\telegram\\ext\\updater.py\", line 597, in polling_action_cb\n",
      "    updates = self.bot.get_updates(\n",
      "  File \"C:\\Users\\JABIR\\AppData\\Roaming\\Python\\Python38\\site-packages\\telegram\\ext\\extbot.py\", line 222, in get_updates\n",
      "    updates = super().get_updates(\n",
      "  File \"C:\\Users\\JABIR\\AppData\\Roaming\\Python\\Python38\\site-packages\\telegram\\bot.py\", line 130, in decorator\n",
      "    result = func(*args, **kwargs)\n",
      "  File \"C:\\Users\\JABIR\\AppData\\Roaming\\Python\\Python38\\site-packages\\telegram\\bot.py\", line 2861, in get_updates\n",
      "    self._post(\n",
      "  File \"C:\\Users\\JABIR\\AppData\\Roaming\\Python\\Python38\\site-packages\\telegram\\bot.py\", line 295, in _post\n",
      "    return self.request.post(\n",
      "  File \"C:\\Users\\JABIR\\AppData\\Roaming\\Python\\Python38\\site-packages\\telegram\\utils\\request.py\", line 356, in post\n",
      "    result = self._request_wrapper(\n",
      "  File \"C:\\Users\\JABIR\\AppData\\Roaming\\Python\\Python38\\site-packages\\telegram\\utils\\request.py\", line 283, in _request_wrapper\n",
      "    raise Conflict(message)\n",
      "telegram.error.Conflict: Conflict: terminated by other getUpdates request; make sure that only one bot instance is running\n",
      "Error while getting Updates: Conflict: terminated by other getUpdates request; make sure that only one bot instance is running\n",
      "No error handlers are registered, logging exception.\n",
      "Traceback (most recent call last):\n",
      "  File \"C:\\Users\\JABIR\\AppData\\Roaming\\Python\\Python38\\site-packages\\telegram\\ext\\updater.py\", line 646, in _network_loop_retry\n",
      "    if not action_cb():\n",
      "  File \"C:\\Users\\JABIR\\AppData\\Roaming\\Python\\Python38\\site-packages\\telegram\\ext\\updater.py\", line 597, in polling_action_cb\n",
      "    updates = self.bot.get_updates(\n",
      "  File \"C:\\Users\\JABIR\\AppData\\Roaming\\Python\\Python38\\site-packages\\telegram\\ext\\extbot.py\", line 222, in get_updates\n",
      "    updates = super().get_updates(\n",
      "  File \"C:\\Users\\JABIR\\AppData\\Roaming\\Python\\Python38\\site-packages\\telegram\\bot.py\", line 130, in decorator\n",
      "    result = func(*args, **kwargs)\n",
      "  File \"C:\\Users\\JABIR\\AppData\\Roaming\\Python\\Python38\\site-packages\\telegram\\bot.py\", line 2861, in get_updates\n",
      "    self._post(\n",
      "  File \"C:\\Users\\JABIR\\AppData\\Roaming\\Python\\Python38\\site-packages\\telegram\\bot.py\", line 295, in _post\n",
      "    return self.request.post(\n",
      "  File \"C:\\Users\\JABIR\\AppData\\Roaming\\Python\\Python38\\site-packages\\telegram\\utils\\request.py\", line 356, in post\n",
      "    result = self._request_wrapper(\n",
      "  File \"C:\\Users\\JABIR\\AppData\\Roaming\\Python\\Python38\\site-packages\\telegram\\utils\\request.py\", line 283, in _request_wrapper\n",
      "    raise Conflict(message)\n",
      "telegram.error.Conflict: Conflict: terminated by other getUpdates request; make sure that only one bot instance is running\n",
      "Error while getting Updates: Conflict: terminated by other getUpdates request; make sure that only one bot instance is running\n",
      "No error handlers are registered, logging exception.\n",
      "Traceback (most recent call last):\n",
      "  File \"C:\\Users\\JABIR\\AppData\\Roaming\\Python\\Python38\\site-packages\\telegram\\ext\\updater.py\", line 646, in _network_loop_retry\n",
      "    if not action_cb():\n",
      "  File \"C:\\Users\\JABIR\\AppData\\Roaming\\Python\\Python38\\site-packages\\telegram\\ext\\updater.py\", line 597, in polling_action_cb\n",
      "    updates = self.bot.get_updates(\n",
      "  File \"C:\\Users\\JABIR\\AppData\\Roaming\\Python\\Python38\\site-packages\\telegram\\ext\\extbot.py\", line 222, in get_updates\n",
      "    updates = super().get_updates(\n",
      "  File \"C:\\Users\\JABIR\\AppData\\Roaming\\Python\\Python38\\site-packages\\telegram\\bot.py\", line 130, in decorator\n",
      "    result = func(*args, **kwargs)\n",
      "  File \"C:\\Users\\JABIR\\AppData\\Roaming\\Python\\Python38\\site-packages\\telegram\\bot.py\", line 2861, in get_updates\n",
      "    self._post(\n",
      "  File \"C:\\Users\\JABIR\\AppData\\Roaming\\Python\\Python38\\site-packages\\telegram\\bot.py\", line 295, in _post\n",
      "    return self.request.post(\n",
      "  File \"C:\\Users\\JABIR\\AppData\\Roaming\\Python\\Python38\\site-packages\\telegram\\utils\\request.py\", line 356, in post\n",
      "    result = self._request_wrapper(\n",
      "  File \"C:\\Users\\JABIR\\AppData\\Roaming\\Python\\Python38\\site-packages\\telegram\\utils\\request.py\", line 283, in _request_wrapper\n",
      "    raise Conflict(message)\n",
      "telegram.error.Conflict: Conflict: terminated by other getUpdates request; make sure that only one bot instance is running\n",
      "Error while getting Updates: Conflict: terminated by other getUpdates request; make sure that only one bot instance is running\n",
      "No error handlers are registered, logging exception.\n",
      "Traceback (most recent call last):\n",
      "  File \"C:\\Users\\JABIR\\AppData\\Roaming\\Python\\Python38\\site-packages\\telegram\\ext\\updater.py\", line 646, in _network_loop_retry\n",
      "    if not action_cb():\n",
      "  File \"C:\\Users\\JABIR\\AppData\\Roaming\\Python\\Python38\\site-packages\\telegram\\ext\\updater.py\", line 597, in polling_action_cb\n",
      "    updates = self.bot.get_updates(\n",
      "  File \"C:\\Users\\JABIR\\AppData\\Roaming\\Python\\Python38\\site-packages\\telegram\\ext\\extbot.py\", line 222, in get_updates\n",
      "    updates = super().get_updates(\n",
      "  File \"C:\\Users\\JABIR\\AppData\\Roaming\\Python\\Python38\\site-packages\\telegram\\bot.py\", line 130, in decorator\n",
      "    result = func(*args, **kwargs)\n",
      "  File \"C:\\Users\\JABIR\\AppData\\Roaming\\Python\\Python38\\site-packages\\telegram\\bot.py\", line 2861, in get_updates\n",
      "    self._post(\n",
      "  File \"C:\\Users\\JABIR\\AppData\\Roaming\\Python\\Python38\\site-packages\\telegram\\bot.py\", line 295, in _post\n",
      "    return self.request.post(\n",
      "  File \"C:\\Users\\JABIR\\AppData\\Roaming\\Python\\Python38\\site-packages\\telegram\\utils\\request.py\", line 356, in post\n",
      "    result = self._request_wrapper(\n",
      "  File \"C:\\Users\\JABIR\\AppData\\Roaming\\Python\\Python38\\site-packages\\telegram\\utils\\request.py\", line 283, in _request_wrapper\n",
      "    raise Conflict(message)\n",
      "telegram.error.Conflict: Conflict: terminated by other getUpdates request; make sure that only one bot instance is running\n",
      "Error while getting Updates: Conflict: terminated by other getUpdates request; make sure that only one bot instance is running\n",
      "No error handlers are registered, logging exception.\n",
      "Traceback (most recent call last):\n",
      "  File \"C:\\Users\\JABIR\\AppData\\Roaming\\Python\\Python38\\site-packages\\telegram\\ext\\updater.py\", line 646, in _network_loop_retry\n",
      "    if not action_cb():\n",
      "  File \"C:\\Users\\JABIR\\AppData\\Roaming\\Python\\Python38\\site-packages\\telegram\\ext\\updater.py\", line 597, in polling_action_cb\n",
      "    updates = self.bot.get_updates(\n",
      "  File \"C:\\Users\\JABIR\\AppData\\Roaming\\Python\\Python38\\site-packages\\telegram\\ext\\extbot.py\", line 222, in get_updates\n",
      "    updates = super().get_updates(\n",
      "  File \"C:\\Users\\JABIR\\AppData\\Roaming\\Python\\Python38\\site-packages\\telegram\\bot.py\", line 130, in decorator\n",
      "    result = func(*args, **kwargs)\n",
      "  File \"C:\\Users\\JABIR\\AppData\\Roaming\\Python\\Python38\\site-packages\\telegram\\bot.py\", line 2861, in get_updates\n",
      "    self._post(\n",
      "  File \"C:\\Users\\JABIR\\AppData\\Roaming\\Python\\Python38\\site-packages\\telegram\\bot.py\", line 295, in _post\n",
      "    return self.request.post(\n",
      "  File \"C:\\Users\\JABIR\\AppData\\Roaming\\Python\\Python38\\site-packages\\telegram\\utils\\request.py\", line 356, in post\n",
      "    result = self._request_wrapper(\n",
      "  File \"C:\\Users\\JABIR\\AppData\\Roaming\\Python\\Python38\\site-packages\\telegram\\utils\\request.py\", line 283, in _request_wrapper\n",
      "    raise Conflict(message)\n",
      "telegram.error.Conflict: Conflict: terminated by other getUpdates request; make sure that only one bot instance is running\n"
     ]
    },
    {
     "name": "stderr",
     "output_type": "stream",
     "text": [
      "Error while getting Updates: Conflict: terminated by other getUpdates request; make sure that only one bot instance is running\n",
      "No error handlers are registered, logging exception.\n",
      "Traceback (most recent call last):\n",
      "  File \"C:\\Users\\JABIR\\AppData\\Roaming\\Python\\Python38\\site-packages\\telegram\\ext\\updater.py\", line 646, in _network_loop_retry\n",
      "    if not action_cb():\n",
      "  File \"C:\\Users\\JABIR\\AppData\\Roaming\\Python\\Python38\\site-packages\\telegram\\ext\\updater.py\", line 597, in polling_action_cb\n",
      "    updates = self.bot.get_updates(\n",
      "  File \"C:\\Users\\JABIR\\AppData\\Roaming\\Python\\Python38\\site-packages\\telegram\\ext\\extbot.py\", line 222, in get_updates\n",
      "    updates = super().get_updates(\n",
      "  File \"C:\\Users\\JABIR\\AppData\\Roaming\\Python\\Python38\\site-packages\\telegram\\bot.py\", line 130, in decorator\n",
      "    result = func(*args, **kwargs)\n",
      "  File \"C:\\Users\\JABIR\\AppData\\Roaming\\Python\\Python38\\site-packages\\telegram\\bot.py\", line 2861, in get_updates\n",
      "    self._post(\n",
      "  File \"C:\\Users\\JABIR\\AppData\\Roaming\\Python\\Python38\\site-packages\\telegram\\bot.py\", line 295, in _post\n",
      "    return self.request.post(\n",
      "  File \"C:\\Users\\JABIR\\AppData\\Roaming\\Python\\Python38\\site-packages\\telegram\\utils\\request.py\", line 356, in post\n",
      "    result = self._request_wrapper(\n",
      "  File \"C:\\Users\\JABIR\\AppData\\Roaming\\Python\\Python38\\site-packages\\telegram\\utils\\request.py\", line 283, in _request_wrapper\n",
      "    raise Conflict(message)\n",
      "telegram.error.Conflict: Conflict: terminated by other getUpdates request; make sure that only one bot instance is running\n",
      "Error while getting Updates: Conflict: terminated by other getUpdates request; make sure that only one bot instance is running\n",
      "No error handlers are registered, logging exception.\n",
      "Traceback (most recent call last):\n",
      "  File \"C:\\Users\\JABIR\\AppData\\Roaming\\Python\\Python38\\site-packages\\telegram\\ext\\updater.py\", line 646, in _network_loop_retry\n",
      "    if not action_cb():\n",
      "  File \"C:\\Users\\JABIR\\AppData\\Roaming\\Python\\Python38\\site-packages\\telegram\\ext\\updater.py\", line 597, in polling_action_cb\n",
      "    updates = self.bot.get_updates(\n",
      "  File \"C:\\Users\\JABIR\\AppData\\Roaming\\Python\\Python38\\site-packages\\telegram\\ext\\extbot.py\", line 222, in get_updates\n",
      "    updates = super().get_updates(\n",
      "  File \"C:\\Users\\JABIR\\AppData\\Roaming\\Python\\Python38\\site-packages\\telegram\\bot.py\", line 130, in decorator\n",
      "    result = func(*args, **kwargs)\n",
      "  File \"C:\\Users\\JABIR\\AppData\\Roaming\\Python\\Python38\\site-packages\\telegram\\bot.py\", line 2861, in get_updates\n",
      "    self._post(\n",
      "  File \"C:\\Users\\JABIR\\AppData\\Roaming\\Python\\Python38\\site-packages\\telegram\\bot.py\", line 295, in _post\n",
      "    return self.request.post(\n",
      "  File \"C:\\Users\\JABIR\\AppData\\Roaming\\Python\\Python38\\site-packages\\telegram\\utils\\request.py\", line 356, in post\n",
      "    result = self._request_wrapper(\n",
      "  File \"C:\\Users\\JABIR\\AppData\\Roaming\\Python\\Python38\\site-packages\\telegram\\utils\\request.py\", line 283, in _request_wrapper\n",
      "    raise Conflict(message)\n",
      "telegram.error.Conflict: Conflict: terminated by other getUpdates request; make sure that only one bot instance is running\n",
      "Error while getting Updates: Conflict: terminated by other getUpdates request; make sure that only one bot instance is running\n",
      "No error handlers are registered, logging exception.\n",
      "Traceback (most recent call last):\n",
      "  File \"C:\\Users\\JABIR\\AppData\\Roaming\\Python\\Python38\\site-packages\\telegram\\ext\\updater.py\", line 646, in _network_loop_retry\n",
      "    if not action_cb():\n",
      "  File \"C:\\Users\\JABIR\\AppData\\Roaming\\Python\\Python38\\site-packages\\telegram\\ext\\updater.py\", line 597, in polling_action_cb\n",
      "    updates = self.bot.get_updates(\n",
      "  File \"C:\\Users\\JABIR\\AppData\\Roaming\\Python\\Python38\\site-packages\\telegram\\ext\\extbot.py\", line 222, in get_updates\n",
      "    updates = super().get_updates(\n",
      "  File \"C:\\Users\\JABIR\\AppData\\Roaming\\Python\\Python38\\site-packages\\telegram\\bot.py\", line 130, in decorator\n",
      "    result = func(*args, **kwargs)\n",
      "  File \"C:\\Users\\JABIR\\AppData\\Roaming\\Python\\Python38\\site-packages\\telegram\\bot.py\", line 2861, in get_updates\n",
      "    self._post(\n",
      "  File \"C:\\Users\\JABIR\\AppData\\Roaming\\Python\\Python38\\site-packages\\telegram\\bot.py\", line 295, in _post\n",
      "    return self.request.post(\n",
      "  File \"C:\\Users\\JABIR\\AppData\\Roaming\\Python\\Python38\\site-packages\\telegram\\utils\\request.py\", line 356, in post\n",
      "    result = self._request_wrapper(\n",
      "  File \"C:\\Users\\JABIR\\AppData\\Roaming\\Python\\Python38\\site-packages\\telegram\\utils\\request.py\", line 283, in _request_wrapper\n",
      "    raise Conflict(message)\n",
      "telegram.error.Conflict: Conflict: terminated by other getUpdates request; make sure that only one bot instance is running\n",
      "Error while getting Updates: Conflict: terminated by other getUpdates request; make sure that only one bot instance is running\n",
      "No error handlers are registered, logging exception.\n",
      "Traceback (most recent call last):\n",
      "  File \"C:\\Users\\JABIR\\AppData\\Roaming\\Python\\Python38\\site-packages\\telegram\\ext\\updater.py\", line 646, in _network_loop_retry\n",
      "    if not action_cb():\n",
      "  File \"C:\\Users\\JABIR\\AppData\\Roaming\\Python\\Python38\\site-packages\\telegram\\ext\\updater.py\", line 597, in polling_action_cb\n",
      "    updates = self.bot.get_updates(\n",
      "  File \"C:\\Users\\JABIR\\AppData\\Roaming\\Python\\Python38\\site-packages\\telegram\\ext\\extbot.py\", line 222, in get_updates\n",
      "    updates = super().get_updates(\n",
      "  File \"C:\\Users\\JABIR\\AppData\\Roaming\\Python\\Python38\\site-packages\\telegram\\bot.py\", line 130, in decorator\n",
      "    result = func(*args, **kwargs)\n",
      "  File \"C:\\Users\\JABIR\\AppData\\Roaming\\Python\\Python38\\site-packages\\telegram\\bot.py\", line 2861, in get_updates\n",
      "    self._post(\n",
      "  File \"C:\\Users\\JABIR\\AppData\\Roaming\\Python\\Python38\\site-packages\\telegram\\bot.py\", line 295, in _post\n",
      "    return self.request.post(\n",
      "  File \"C:\\Users\\JABIR\\AppData\\Roaming\\Python\\Python38\\site-packages\\telegram\\utils\\request.py\", line 356, in post\n",
      "    result = self._request_wrapper(\n",
      "  File \"C:\\Users\\JABIR\\AppData\\Roaming\\Python\\Python38\\site-packages\\telegram\\utils\\request.py\", line 283, in _request_wrapper\n",
      "    raise Conflict(message)\n",
      "telegram.error.Conflict: Conflict: terminated by other getUpdates request; make sure that only one bot instance is running\n",
      "Error while getting Updates: Conflict: terminated by other getUpdates request; make sure that only one bot instance is running\n",
      "No error handlers are registered, logging exception.\n",
      "Traceback (most recent call last):\n",
      "  File \"C:\\Users\\JABIR\\AppData\\Roaming\\Python\\Python38\\site-packages\\telegram\\ext\\updater.py\", line 646, in _network_loop_retry\n",
      "    if not action_cb():\n",
      "  File \"C:\\Users\\JABIR\\AppData\\Roaming\\Python\\Python38\\site-packages\\telegram\\ext\\updater.py\", line 597, in polling_action_cb\n",
      "    updates = self.bot.get_updates(\n",
      "  File \"C:\\Users\\JABIR\\AppData\\Roaming\\Python\\Python38\\site-packages\\telegram\\ext\\extbot.py\", line 222, in get_updates\n",
      "    updates = super().get_updates(\n",
      "  File \"C:\\Users\\JABIR\\AppData\\Roaming\\Python\\Python38\\site-packages\\telegram\\bot.py\", line 130, in decorator\n",
      "    result = func(*args, **kwargs)\n",
      "  File \"C:\\Users\\JABIR\\AppData\\Roaming\\Python\\Python38\\site-packages\\telegram\\bot.py\", line 2861, in get_updates\n",
      "    self._post(\n",
      "  File \"C:\\Users\\JABIR\\AppData\\Roaming\\Python\\Python38\\site-packages\\telegram\\bot.py\", line 295, in _post\n",
      "    return self.request.post(\n",
      "  File \"C:\\Users\\JABIR\\AppData\\Roaming\\Python\\Python38\\site-packages\\telegram\\utils\\request.py\", line 356, in post\n",
      "    result = self._request_wrapper(\n",
      "  File \"C:\\Users\\JABIR\\AppData\\Roaming\\Python\\Python38\\site-packages\\telegram\\utils\\request.py\", line 283, in _request_wrapper\n",
      "    raise Conflict(message)\n",
      "telegram.error.Conflict: Conflict: terminated by other getUpdates request; make sure that only one bot instance is running\n",
      "Error while getting Updates: Conflict: terminated by other getUpdates request; make sure that only one bot instance is running\n",
      "No error handlers are registered, logging exception.\n",
      "Traceback (most recent call last):\n",
      "  File \"C:\\Users\\JABIR\\AppData\\Roaming\\Python\\Python38\\site-packages\\telegram\\ext\\updater.py\", line 646, in _network_loop_retry\n",
      "    if not action_cb():\n",
      "  File \"C:\\Users\\JABIR\\AppData\\Roaming\\Python\\Python38\\site-packages\\telegram\\ext\\updater.py\", line 597, in polling_action_cb\n",
      "    updates = self.bot.get_updates(\n",
      "  File \"C:\\Users\\JABIR\\AppData\\Roaming\\Python\\Python38\\site-packages\\telegram\\ext\\extbot.py\", line 222, in get_updates\n",
      "    updates = super().get_updates(\n",
      "  File \"C:\\Users\\JABIR\\AppData\\Roaming\\Python\\Python38\\site-packages\\telegram\\bot.py\", line 130, in decorator\n",
      "    result = func(*args, **kwargs)\n",
      "  File \"C:\\Users\\JABIR\\AppData\\Roaming\\Python\\Python38\\site-packages\\telegram\\bot.py\", line 2861, in get_updates\n",
      "    self._post(\n",
      "  File \"C:\\Users\\JABIR\\AppData\\Roaming\\Python\\Python38\\site-packages\\telegram\\bot.py\", line 295, in _post\n",
      "    return self.request.post(\n",
      "  File \"C:\\Users\\JABIR\\AppData\\Roaming\\Python\\Python38\\site-packages\\telegram\\utils\\request.py\", line 356, in post\n",
      "    result = self._request_wrapper(\n",
      "  File \"C:\\Users\\JABIR\\AppData\\Roaming\\Python\\Python38\\site-packages\\telegram\\utils\\request.py\", line 283, in _request_wrapper\n",
      "    raise Conflict(message)\n",
      "telegram.error.Conflict: Conflict: terminated by other getUpdates request; make sure that only one bot instance is running\n"
     ]
    }
   ],
   "source": [
    "import requests\n",
    "import json\n",
    "from telegram.ext import CommandHandler, Updater, MessageHandler, Filters, CallbackQueryHandler\n",
    "\n",
    "TOKEN = '1956719639:AAHqT5hX3PdeXyJUgdgmJZfnEzCiPDb0gWQ'\n",
    "\n",
    "updater = Updater(token=TOKEN, use_context=True)\n",
    "dispatcher = updater.dispatcher\n",
    "\n",
    "welcome_text = \"Welcome to Github user search bot\\n this chatbot is developed by jabir yahaya\\nSearch for a user with '/username'.\"\n",
    "\n",
    "def response(username):\n",
    "    url = f'https://api.github.com/users/{username}'\n",
    "\n",
    "    headers = {\"Accept\": 'application/vnd.github.v3+json'}\n",
    "    r = requests.get(url, headers = headers)\n",
    "\n",
    "    content = r.json()\n",
    "    result = f\"Bio:{content['bio']}\\nName:{content['name']}\"\n",
    "    \n",
    "    return result\n",
    "    \n",
    "def start(update, context):\n",
    "    context.bot.send_message(chat_id=update.effective_chat.id, text=welcome_text)\n",
    "    \n",
    "def user_search(update, context):\n",
    "    context.bot.send_message(chat_id=update.effective_chat.id, text= response('virusj'))\n",
    "    \n",
    "dispatcher.add_handler(CommandHandler('start',start))\n",
    "dispatcher.add_handler(CommandHandler('virusj', user_search))\n",
    "\n",
    "updater.start_polling()\n",
    "updater.idle()"
   ]
  },
  {
   "cell_type": "code",
   "execution_count": null,
   "metadata": {},
   "outputs": [],
   "source": []
  }
 ],
 "metadata": {
  "kernelspec": {
   "display_name": "Python 3",
   "language": "python",
   "name": "python3"
  },
  "language_info": {
   "codemirror_mode": {
    "name": "ipython",
    "version": 3
   },
   "file_extension": ".py",
   "mimetype": "text/x-python",
   "name": "python",
   "nbconvert_exporter": "python",
   "pygments_lexer": "ipython3",
   "version": "3.8.5"
  }
 },
 "nbformat": 4,
 "nbformat_minor": 4
}
